Workbook
Name Identificacao: Dashboard!$A$3:$X$3
Name Exames: Gastos!$B$3:$H$2999
Name Exames: Exames!$B$3:$I$2999
Name FormasPagamentos: 'Parâmetros'!$L$4:$L$995
Name TiposExames: 'Parâmetros'!$B$3:$D$995
Name SlicerCache_Table_1_Col_1: #N/A
Name SlicerCache_Table_1_Col_3: #N/A
Name SlicerCache_Table_2_Col_13: #N/A
Name SlicerCache_Table_2_Col_14: #N/A

Sheet Dashboard
C1: CONTROLE DE EXAMES DE IMAGENS VETERINÁRIOS
D3: Nome: | E3: Inserir Nome | T3: Faixa: | U3: ='Dashboard-Dados'!$AF$17 -> Branca
C5: Receita | G5: Despesa | K5: Lucro | O5: Exames Totais | S5: Máx. Exames x Mês
C6: ='Dashboard-Dados'!AF1 -> 0 | G6: ='Dashboard-Dados'!AF2 -> 0 | K6: ='Dashboard-Dados'!AF3 -> 0 | O6: ='Dashboard-Dados'!AF5 -> 0 | S6: ='Dashboard-Dados'!AG5 -> 0
Z7: FORMATAÇÃO
B8: Receita Total x Despesa Total | Z8: =IFERROR(__xludf.DUMMYFUNCTION("QUERY({'Dashboard-Dados'!AE7:AI14},""Select Col1, Col5"")"),"Faixas Cor") -> Faixas Cor | AA8: =IFERROR(__xludf.DUMMYFUNCTION("""COMPUTED_VALUE""")," Alvo") -> Alvo
D9: =IFERROR(__xludf.DUMMYFUNCTION("SPARKLINE(C17,{""charttype"",""column"";""ymin"", 0; ""ymax"",MAX(C17:G17);""firstcolor"",""#93c47d""})"),"") | H9: =IFERROR(__xludf.DUMMYFUNCTION("SPARKLINE(G17,{""charttype"",""column"";""ymin"", 0; ""ymax"",MAX(C17:G17);""firstcolor"",""#ea4335""})"),"") | Z9: =IFERROR(__xludf.DUMMYFUNCTION("""COMPUTED_VALUE"""),"31") -> 31
Z10: =IFERROR(__xludf.DUMMYFUNCTION("""COMPUTED_VALUE"""),"Branca") -> Branca | AA10: =IFERROR(__xludf.DUMMYFUNCTION("""COMPUTED_VALUE"""),TRUE) -> TRUE
Z11: =IFERROR(__xludf.DUMMYFUNCTION("""COMPUTED_VALUE"""),"Amarela") -> Amarela | AA11: =IFERROR(__xludf.DUMMYFUNCTION("""COMPUTED_VALUE"""),FALSE) -> FALSE
Z12: =IFERROR(__xludf.DUMMYFUNCTION("""COMPUTED_VALUE"""),"Roxa") -> Roxa | AA12: =IFERROR(__xludf.DUMMYFUNCTION("""COMPUTED_VALUE"""),FALSE) -> FALSE
Z13: =IFERROR(__xludf.DUMMYFUNCTION("""COMPUTED_VALUE"""),"Marrom") -> Marrom | AA13: =IFERROR(__xludf.DUMMYFUNCTION("""COMPUTED_VALUE"""),FALSE) -> FALSE
Z14: =IFERROR(__xludf.DUMMYFUNCTION("""COMPUTED_VALUE"""),"Preta") -> Preta | AA14: =IFERROR(__xludf.DUMMYFUNCTION("""COMPUTED_VALUE"""),FALSE) -> FALSE
D16: Receita | H16: Despesa
C17: =IF(ISBLANK('Dashboard-Dados'!AF1),0,'Dashboard-Dados'!AF1) -> 0 | G17: =IF(ISBLANK('Dashboard-Dados'!AF2),0,'Dashboard-Dados'!AF2) -> 0
AK48: SUM de | AL48: SUM de | AM48: SUM de | AN48: SUM de | AO48: MAX de
AK49: 0 | AL49: 0 | AM49: 0 | AN49: 0 | AO49: 0

Sheet Exames
B1: CONTROLE DE EXAMES DE IMAGENS VETERINÁRIOS
B3: Data Exame | C3: Vet Solicitante | D3: Clínica | E3: Animal | F3: Tipo de Exame | G3: Exame Específico | H3: Valor Exame | I3: Forma Pagamento | K3: Exame | L3: Valor Recebido | M3: Mês-N | N3: Mês | O3: Ano
F4: Ultrassonografia | H4: 120 | I4: Boleto | K4: =IFERROR(__xludf.DUMMYFUNCTION("IF(ISBLANK(B4),"""",IF(ISDATE(B4),""X"",""""))"),"") | L4: =IFERROR(__xludf.DUMMYFUNCTION("IF(ISBLANK(B4),"""",IF(Or(I4=""Em Aberto"",ISBLANK(I4),NOT(ISDATE(B4))),"""",H4))"),"") | M4: =IFERROR(__xludf.DUMMYFUNCTION("IF(ISBLANK(B4),"""",IF(ISDATE(B4),TEXT(B4,""m""),""""))"),"") | N4: =IFERROR(__xludf.DUMMYFUNCTION("IF(M4="""","""",QUERY({'Dashboard-Dados'!$Y$2:$AA$13},""Select Col2 Where Col1=""&M4))"),"") | O4: =IFERROR(__xludf.DUMMYFUNCTION("IF(ISBLANK(B4),"""",IF(ISDATE(B4),TEXT(B4,""yyyy""),""""))"),"")
K5: =IFERROR(__xludf.DUMMYFUNCTION("IF(ISBLANK(B5),"""",IF(ISDATE(B5),""X"",""""))"),"") | L5: =IFERROR(__xludf.DUMMYFUNCTION("IF(ISBLANK(B5),"""",IF(Or(I5=""Em Aberto"",ISBLANK(I5),NOT(ISDATE(B5))),"""",H5))"),"") | M5: =IFERROR(__xludf.DUMMYFUNCTION("IF(ISBLANK(B5),"""",IF(ISDATE(B5),TEXT(B5,""m""),""""))"),"") | N5: =IFERROR(__xludf.DUMMYFUNCTION("IF(M5="""","""",QUERY({'Dashboard-Dados'!$Y$2:$AA$13},""Select Col2 Where Col1=""&M5))"),"") | O5: =IFERROR(__xludf.DUMMYFUNCTION("IF(ISBLANK(B5),"""",IF(ISDATE(B5),TEXT(B5,""yyyy""),""""))"),"")
K6: =IFERROR(__xludf.DUMMYFUNCTION("IF(ISBLANK(B6),"""",IF(ISDATE(B6),""X"",""""))"),"") | L6: =IFERROR(__xludf.DUMMYFUNCTION("IF(ISBLANK(B6),"""",IF(Or(I6=""Em Aberto"",ISBLANK(I6),NOT(ISDATE(B6))),"""",H6))"),"") | M6: =IFERROR(__xludf.DUMMYFUNCTION("IF(ISBLANK(B6),"""",IF(ISDATE(B6),TEXT(B6,""m""),""""))"),"") | N6: =IFERROR(__xludf.DUMMYFUNCTION("IF(M6="""","""",QUERY({'Dashboard-Dados'!$Y$2:$AA$13},""Select Col2 Where Col1=""&M6))"),"") | O6: =IFERROR(__xludf.DUMMYFUNCTION("IF(ISBLANK(B6),"""",IF(ISDATE(B6),TEXT(B6,""yyyy""),""""))"),"")
K7: =IFERROR(__xludf.DUMMYFUNCTION("IF(ISBLANK(B7),"""",IF(ISDATE(B7),""X"",""""))"),"") | L7: =IFERROR(__xludf.DUMMYFUNCTION("IF(ISBLANK(B7),"""",IF(Or(I7=""Em Aberto"",ISBLANK(I7),NOT(ISDATE(B7))),"""",H7))"),"") | M7: =IFERROR(__xludf.DUMMYFUNCTION("IF(ISBLANK(B7),"""",IF(ISDATE(B7),TEXT(B7,""m""),""""))"),"") | N7: =IFERROR(__xludf.DUMMYFUNCTION("IF(M7="""","""",QUERY({'Dashboard-Dados'!$Y$2:$AA$13},""Select Col2 Where Col1=""&M7))"),"") | O7: =IFERROR(__xludf.DUMMYFUNCTION("IF(ISBLANK(B7),"""",IF(ISDATE(B7),TEXT(B7,""yyyy""),""""))"),"")
K8: =IFERROR(__xludf.DUMMYFUNCTION("IF(ISBLANK(B8),"""",IF(ISDATE(B8),""X"",""""))"),"") | L8: =IFERROR(__xludf.DUMMYFUNCTION("IF(ISBLANK(B8),"""",IF(Or(I8=""Em Aberto"",ISBLANK(I8),NOT(ISDATE(B8))),"""",H8))"),"") | M8: =IFERROR(__xludf.DUMMYFUNCTION("IF(ISBLANK(B8),"""",IF(ISDATE(B8),TEXT(B8,""m""),""""))"),"") | N8: =IFERROR(__xludf.DUMMYFUNCTION("IF(M8="""","""",QUERY({'Dashboard-Dados'!$Y$2:$AA$13},""Select Col2 Where Col1=""&M8))"),"") | O8: =IFERROR(__xludf.DUMMYFUNCTION("IF(ISBLANK(B8),"""",IF(ISDATE(B8),TEXT(B8,""yyyy""),""""))"),"")
K9: =IFERROR(__xludf.DUMMYFUNCTION("IF(ISBLANK(B9),"""",IF(ISDATE(B9),""X"",""""))"),"") | L9: =IFERROR(__xludf.DUMMYFUNCTION("IF(ISBLANK(B9),"""",IF(Or(I9=""Em Aberto"",ISBLANK(I9),NOT(ISDATE(B9))),"""",H9))"),"") | M9: =IFERROR(__xludf.DUMMYFUNCTION("IF(ISBLANK(B9),"""",IF(ISDATE(B9),TEXT(B9,""m""),""""))"),"") | N9: =IFERROR(__xludf.DUMMYFUNCTION("IF(M9="""","""",QUERY({'Dashboard-Dados'!$Y$2:$AA$13},""Select Col2 Where Col1=""&M9))"),"") | O9: =IFERROR(__xludf.DUMMYFUNCTION("IF(ISBLANK(B9),"""",IF(ISDATE(B9),TEXT(B9,""yyyy""),""""))"),"")
K10: =IFERROR(__xludf.DUMMYFUNCTION("IF(ISBLANK(B10),"""",IF(ISDATE(B10),""X"",""""))"),"") | L10: =IFERROR(__xludf.DUMMYFUNCTION("IF(ISBLANK(B10),"""",IF(Or(I10=""Em Aberto"",ISBLANK(I10),NOT(ISDATE(B10))),"""",H10))"),"") | M10: =IFERROR(__xludf.DUMMYFUNCTION("IF(ISBLANK(B10),"""",IF(ISDATE(B10),TEXT(B10,""m""),""""))"),"") | N10: =IFERROR(__xludf.DUMMYFUNCTION("IF(M10="""","""",QUERY({'Dashboard-Dados'!$Y$2:$AA$13},""Select Col2 Where Col1=""&M10))"),"") | O10: =IFERROR(__xludf.DUMMYFUNCTION("IF(ISBLANK(B10),"""",IF(ISDATE(B10),TEXT(B10,""yyyy""),""""))"),"")
K11: =IFERROR(__xludf.DUMMYFUNCTION("IF(ISBLANK(B11),"""",IF(ISDATE(B11),""X"",""""))"),"") | L11: =IFERROR(__xludf.DUMMYFUNCTION("IF(ISBLANK(B11),"""",IF(Or(I11=""Em Aberto"",ISBLANK(I11),NOT(ISDATE(B11))),"""",H11))"),"") | M11: =IFERROR(__xludf.DUMMYFUNCTION("IF(ISBLANK(B11),"""",IF(ISDATE(B11),TEXT(B11,""m""),""""))"),"") | N11: =IFERROR(__xludf.DUMMYFUNCTION("IF(M11="""","""",QUERY({'Dashboard-Dados'!$Y$2:$AA$13},""Select Col2 Where Col1=""&M11))"),"") | O11: =IFERROR(__xludf.DUMMYFUNCTION("IF(ISBLANK(B11),"""",IF(ISDATE(B11),TEXT(B11,""yyyy""),""""))"),"")
K12: =IFERROR(__xludf.DUMMYFUNCTION("IF(ISBLANK(B12),"""",IF(ISDATE(B12),""X"",""""))"),"") | L12: =IFERROR(__xludf.DUMMYFUNCTION("IF(ISBLANK(B12),"""",IF(Or(I12=""Em Aberto"",ISBLANK(I12),NOT(ISDATE(B12))),"""",H12))"),"") | M12: =IFERROR(__xludf.DUMMYFUNCTION("IF(ISBLANK(B12),"""",IF(ISDATE(B12),TEXT(B12,""m""),""""))"),"") | N12: =IFERROR(__xludf.DUMMYFUNCTION("IF(M12="""","""",QUERY({'Dashboard-Dados'!$Y$2:$AA$13},""Select Col2 Where Col1=""&M12))"),"") | O12: =IFERROR(__xludf.DUMMYFUNCTION("IF(ISBLANK(B12),"""",IF(ISDATE(B12),TEXT(B12,""yyyy""),""""))"),"")
K13: =IFERROR(__xludf.DUMMYFUNCTION("IF(ISBLANK(B13),"""",IF(ISDATE(B13),""X"",""""))"),"") | L13: =IFERROR(__xludf.DUMMYFUNCTION("IF(ISBLANK(B13),"""",IF(Or(I13=""Em Aberto"",ISBLANK(I13),NOT(ISDATE(B13))),"""",H13))"),"") | M13: =IFERROR(__xludf.DUMMYFUNCTION("IF(ISBLANK(B13),"""",IF(ISDATE(B13),TEXT(B13,""m""),""""))"),"") | N13: =IFERROR(__xludf.DUMMYFUNCTION("IF(M13="""","""",QUERY({'Dashboard-Dados'!$Y$2:$AA$13},""Select Col2 Where Col1=""&M13))"),"") | O13: =IFERROR(__xludf.DUMMYFUNCTION("IF(ISBLANK(B13),"""",IF(ISDATE(B13),TEXT(B13,""yyyy""),""""))"),"")
K14: =IFERROR(__xludf.DUMMYFUNCTION("IF(ISBLANK(B14),"""",IF(ISDATE(B14),""X"",""""))"),"") | L14: =IFERROR(__xludf.DUMMYFUNCTION("IF(ISBLANK(B14),"""",IF(Or(I14=""Em Aberto"",ISBLANK(I14),NOT(ISDATE(B14))),"""",H14))"),"") | M14: =IFERROR(__xludf.DUMMYFUNCTION("IF(ISBLANK(B14),"""",IF(ISDATE(B14),TEXT(B14,""m""),""""))"),"") | N14: =IFERROR(__xludf.DUMMYFUNCTION("IF(M14="""","""",QUERY({'Dashboard-Dados'!$Y$2:$AA$13},""Select Col2 Where Col1=""&M14))"),"") | O14: =IFERROR(__xludf.DUMMYFUNCTION("IF(ISBLANK(B14),"""",IF(ISDATE(B14),TEXT(B14,""yyyy""),""""))"),"")
K15: =IFERROR(__xludf.DUMMYFUNCTION("IF(ISBLANK(B15),"""",IF(ISDATE(B15),""X"",""""))"),"") | L15: =IFERROR(__xludf.DUMMYFUNCTION("IF(ISBLANK(B15),"""",IF(Or(I15=""Em Aberto"",ISBLANK(I15),NOT(ISDATE(B15))),"""",H15))"),"") | M15: =IFERROR(__xludf.DUMMYFUNCTION("IF(ISBLANK(B15),"""",IF(ISDATE(B15),TEXT(B15,""m""),""""))"),"") | N15: =IFERROR(__xludf.DUMMYFUNCTION("IF(M15="""","""",QUERY({'Dashboard-Dados'!$Y$2:$AA$13},""Select Col2 Where Col1=""&M15))"),"") | O15: =IFERROR(__xludf.DUMMYFUNCTION("IF(ISBLANK(B15),"""",IF(ISDATE(B15),TEXT(B15,""yyyy""),""""))"),"")
K16: =IFERROR(__xludf.DUMMYFUNCTION("IF(ISBLANK(B16),"""",IF(ISDATE(B16),""X"",""""))"),"") | L16: =IFERROR(__xludf.DUMMYFUNCTION("IF(ISBLANK(B16),"""",IF(Or(I16=""Em Aberto"",ISBLANK(I16),NOT(ISDATE(B16))),"""",H16))"),"") | M16: =IFERROR(__xludf.DUMMYFUNCTION("IF(ISBLANK(B16),"""",IF(ISDATE(B16),TEXT(B16,""m""),""""))"),"") | N16: =IFERROR(__xludf.DUMMYFUNCTION("IF(M16="""","""",QUERY({'Dashboard-Dados'!$Y$2:$AA$13},""Select Col2 Where Col1=""&M16))"),"") | O16: =IFERROR(__xludf.DUMMYFUNCTION("IF(ISBLANK(B16),"""",IF(ISDATE(B16),TEXT(B16,""yyyy""),""""))"),"")
K17: =IFERROR(__xludf.DUMMYFUNCTION("IF(ISBLANK(B17),"""",IF(ISDATE(B17),""X"",""""))"),"") | L17: =IFERROR(__xludf.DUMMYFUNCTION("IF(ISBLANK(B17),"""",IF(Or(I17=""Em Aberto"",ISBLANK(I17),NOT(ISDATE(B17))),"""",H17))"),"") | M17: =IFERROR(__xludf.DUMMYFUNCTION("IF(ISBLANK(B17),"""",IF(ISDATE(B17),TEXT(B17,""m""),""""))"),"") | N17: =IFERROR(__xludf.DUMMYFUNCTION("IF(M17="""","""",QUERY({'Dashboard-Dados'!$Y$2:$AA$13},""Select Col2 Where Col1=""&M17))"),"") | O17: =IFERROR(__xludf.DUMMYFUNCTION("IF(ISBLANK(B17),"""",IF(ISDATE(B17),TEXT(B17,""yyyy""),""""))"),"")
K18: =IFERROR(__xludf.DUMMYFUNCTION("IF(ISBLANK(B18),"""",IF(ISDATE(B18),""X"",""""))"),"") | L18: =IFERROR(__xludf.DUMMYFUNCTION("IF(ISBLANK(B18),"""",IF(Or(I18=""Em Aberto"",ISBLANK(I18),NOT(ISDATE(B18))),"""",H18))"),"") | M18: =IFERROR(__xludf.DUMMYFUNCTION("IF(ISBLANK(B18),"""",IF(ISDATE(B18),TEXT(B18,""m""),""""))"),"") | N18: =IFERROR(__xludf.DUMMYFUNCTION("IF(M18="""","""",QUERY({'Dashboard-Dados'!$Y$2:$AA$13},""Select Col2 Where Col1=""&M18))"),"") | O18: =IFERROR(__xludf.DUMMYFUNCTION("IF(ISBLANK(B18),"""",IF(ISDATE(B18),TEXT(B18,""yyyy""),""""))"),"")
K19: =IFERROR(__xludf.DUMMYFUNCTION("IF(ISBLANK(B19),"""",IF(ISDATE(B19),""X"",""""))"),"") | L19: =IFERROR(__xludf.DUMMYFUNCTION("IF(ISBLANK(B19),"""",IF(Or(I19=""Em Aberto"",ISBLANK(I19),NOT(ISDATE(B19))),"""",H19))"),"") | M19: =IFERROR(__xludf.DUMMYFUNCTION("IF(ISBLANK(B19),"""",IF(ISDATE(B19),TEXT(B19,""m""),""""))"),"") | N19: =IFERROR(__xludf.DUMMYFUNCTION("IF(M19="""","""",QUERY({'Dashboard-Dados'!$Y$2:$AA$13},""Select Col2 Where Col1=""&M19))"),"") | O19: =IFERROR(__xludf.DUMMYFUNCTION("IF(ISBLANK(B19),"""",IF(ISDATE(B19),TEXT(B19,""yyyy""),""""))"),"")
K20: =IFERROR(__xludf.DUMMYFUNCTION("IF(ISBLANK(B20),"""",IF(ISDATE(B20),""X"",""""))"),"") | L20: =IFERROR(__xludf.DUMMYFUNCTION("IF(ISBLANK(B20),"""",IF(Or(I20=""Em Aberto"",ISBLANK(I20),NOT(ISDATE(B20))),"""",H20))"),"") | M20: =IFERROR(__xludf.DUMMYFUNCTION("IF(ISBLANK(B20),"""",IF(ISDATE(B20),TEXT(B20,""m""),""""))"),"") | N20: =IFERROR(__xludf.DUMMYFUNCTION("IF(M20="""","""",QUERY({'Dashboard-Dados'!$Y$2:$AA$13},""Select Col2 Where Col1=""&M20))"),"") | O20: =IFERROR(__xludf.DUMMYFUNCTION("IF(ISBLANK(B20),"""",IF(ISDATE(B20),TEXT(B20,""yyyy""),""""))"),"")
K21: =IFERROR(__xludf.DUMMYFUNCTION("IF(ISBLANK(B21),"""",IF(ISDATE(B21),""X"",""""))"),"") | L21: =IFERROR(__xludf.DUMMYFUNCTION("IF(ISBLANK(B21),"""",IF(Or(I21=""Em Aberto"",ISBLANK(I21),NOT(ISDATE(B21))),"""",H21))"),"") | M21: =IFERROR(__xludf.DUMMYFUNCTION("IF(ISBLANK(B21),"""",IF(ISDATE(B21),TEXT(B21,""m""),""""))"),"") | N21: =IFERROR(__xludf.DUMMYFUNCTION("IF(M21="""","""",QUERY({'Dashboard-Dados'!$Y$2:$AA$13},""Select Col2 Where Col1=""&M21))"),"") | O21: =IFERROR(__xludf.DUMMYFUNCTION("IF(ISBLANK(B21),"""",IF(ISDATE(B21),TEXT(B21,""yyyy""),""""))"),"")
K22: =IFERROR(__xludf.DUMMYFUNCTION("IF(ISBLANK(B22),"""",IF(ISDATE(B22),""X"",""""))"),"") | L22: =IFERROR(__xludf.DUMMYFUNCTION("IF(ISBLANK(B22),"""",IF(Or(I22=""Em Aberto"",ISBLANK(I22),NOT(ISDATE(B22))),"""",H22))"),"") | M22: =IFERROR(__xludf.DUMMYFUNCTION("IF(ISBLANK(B22),"""",IF(ISDATE(B22),TEXT(B22,""m""),""""))"),"") | N22: =IFERROR(__xludf.DUMMYFUNCTION("IF(M22="""","""",QUERY({'Dashboard-Dados'!$Y$2:$AA$13},""Select Col2 Where Col1=""&M22))"),"") | O22: =IFERROR(__xludf.DUMMYFUNCTION("IF(ISBLANK(B22),"""",IF(ISDATE(B22),TEXT(B22,""yyyy""),""""))"),"")
K23: =IFERROR(__xludf.DUMMYFUNCTION("IF(ISBLANK(B23),"""",IF(ISDATE(B23),""X"",""""))"),"") | L23: =IFERROR(__xludf.DUMMYFUNCTION("IF(ISBLANK(B23),"""",IF(Or(I23=""Em Aberto"",ISBLANK(I23),NOT(ISDATE(B23))),"""",H23))"),"") | M23: =IFERROR(__xludf.DUMMYFUNCTION("IF(ISBLANK(B23),"""",IF(ISDATE(B23),TEXT(B23,""m""),""""))"),"") | N23: =IFERROR(__xludf.DUMMYFUNCTION("IF(M23="""","""",QUERY({'Dashboard-Dados'!$Y$2:$AA$13},""Select Col2 Where Col1=""&M23))"),"") | O23: =IFERROR(__xludf.DUMMYFUNCTION("IF(ISBLANK(B23),"""",IF(ISDATE(B23),TEXT(B23,""yyyy""),""""))"),"")
K24: =IFERROR(__xludf.DUMMYFUNCTION("IF(ISBLANK(B24),"""",IF(ISDATE(B24),""X"",""""))"),"") | L24: =IFERROR(__xludf.DUMMYFUNCTION("IF(ISBLANK(B24),"""",IF(Or(I24=""Em Aberto"",ISBLANK(I24),NOT(ISDATE(B24))),"""",H24))"),"") | M24: =IFERROR(__xludf.DUMMYFUNCTION("IF(ISBLANK(B24),"""",IF(ISDATE(B24),TEXT(B24,""m""),""""))"),"") | N24: =IFERROR(__xludf.DUMMYFUNCTION("IF(M24="""","""",QUERY({'Dashboard-Dados'!$Y$2:$AA$13},""Select Col2 Where Col1=""&M24))"),"") | O24: =IFERROR(__xludf.DUMMYFUNCTION("IF(ISBLANK(B24),"""",IF(ISDATE(B24),TEXT(B24,""yyyy""),""""))"),"")
K25: =IFERROR(__xludf.DUMMYFUNCTION("IF(ISBLANK(B25),"""",IF(ISDATE(B25),""X"",""""))"),"") | L25: =IFERROR(__xludf.DUMMYFUNCTION("IF(ISBLANK(B25),"""",IF(Or(I25=""Em Aberto"",ISBLANK(I25),NOT(ISDATE(B25))),"""",H25))"),"") | M25: =IFERROR(__xludf.DUMMYFUNCTION("IF(ISBLANK(B25),"""",IF(ISDATE(B25),TEXT(B25,""m""),""""))"),"") | N25: =IFERROR(__xludf.DUMMYFUNCTION("IF(M25="""","""",QUERY({'Dashboard-Dados'!$Y$2:$AA$13},""Select Col2 Where Col1=""&M25))"),"") | O25: =IFERROR(__xludf.DUMMYFUNCTION("IF(ISBLANK(B25),"""",IF(ISDATE(B25),TEXT(B25,""yyyy""),""""))"),"")
K26: =IFERROR(__xludf.DUMMYFUNCTION("IF(ISBLANK(B26),"""",IF(ISDATE(B26),""X"",""""))"),"") | L26: =IFERROR(__xludf.DUMMYFUNCTION("IF(ISBLANK(B26),"""",IF(Or(I26=""Em Aberto"",ISBLANK(I26),NOT(ISDATE(B26))),"""",H26))"),"") | M26: =IFERROR(__xludf.DUMMYFUNCTION("IF(ISBLANK(B26),"""",IF(ISDATE(B26),TEXT(B26,""m""),""""))"),"") | N26: =IFERROR(__xludf.DUMMYFUNCTION("IF(M26="""","""",QUERY({'Dashboard-Dados'!$Y$2:$AA$13},""Select Col2 Where Col1=""&M26))"),"") | O26: =IFERROR(__xludf.DUMMYFUNCTION("IF(ISBLANK(B26),"""",IF(ISDATE(B26),TEXT(B26,""yyyy""),""""))"),"")
K27: =IFERROR(__xludf.DUMMYFUNCTION("IF(ISBLANK(B27),"""",IF(ISDATE(B27),""X"",""""))"),"") | L27: =IFERROR(__xludf.DUMMYFUNCTION("IF(ISBLANK(B27),"""",IF(Or(I27=""Em Aberto"",ISBLANK(I27),NOT(ISDATE(B27))),"""",H27))"),"") | M27: =IFERROR(__xludf.DUMMYFUNCTION("IF(ISBLANK(B27),"""",IF(ISDATE(B27),TEXT(B27,""m""),""""))"),"") | N27: =IFERROR(__xludf.DUMMYFUNCTION("IF(M27="""","""",QUERY({'Dashboard-Dados'!$Y$2:$AA$13},""Select Col2 Where Col1=""&M27))"),"") | O27: =IFERROR(__xludf.DUMMYFUNCTION("IF(ISBLANK(B27),"""",IF(ISDATE(B27),TEXT(B27,""yyyy""),""""))"),"")
K28: =IFERROR(__xludf.DUMMYFUNCTION("IF(ISBLANK(B28),"""",IF(ISDATE(B28),""X"",""""))"),"") | L28: =IFERROR(__xludf.DUMMYFUNCTION("IF(ISBLANK(B28),"""",IF(Or(I28=""Em Aberto"",ISBLANK(I28),NOT(ISDATE(B28))),"""",H28))"),"") | M28: =IFERROR(__xludf.DUMMYFUNCTION("IF(ISBLANK(B28),"""",IF(ISDATE(B28),TEXT(B28,""m""),""""))"),"") | N28: =IFERROR(__xludf.DUMMYFUNCTION("IF(M28="""","""",QUERY({'Dashboard-Dados'!$Y$2:$AA$13},""Select Col2 Where Col1=""&M28))"),"") | O28: =IFERROR(__xludf.DUMMYFUNCTION("IF(ISBLANK(B28),"""",IF(ISDATE(B28),TEXT(B28,""yyyy""),""""))"),"")
K29: =IFERROR(__xludf.DUMMYFUNCTION("IF(ISBLANK(B29),"""",IF(ISDATE(B29),""X"",""""))"),"") | L29: =IFERROR(__xludf.DUMMYFUNCTION("IF(ISBLANK(B29),"""",IF(Or(I29=""Em Aberto"",ISBLANK(I29),NOT(ISDATE(B29))),"""",H29))"),"") | M29: =IFERROR(__xludf.DUMMYFUNCTION("IF(ISBLANK(B29),"""",IF(ISDATE(B29),TEXT(B29,""m""),""""))"),"") | N29: =IFERROR(__xludf.DUMMYFUNCTION("IF(M29="""","""",QUERY({'Dashboard-Dados'!$Y$2:$AA$13},""Select Col2 Where Col1=""&M29))"),"") | O29: =IFERROR(__xludf.DUMMYFUNCTION("IF(ISBLANK(B29),"""",IF(ISDATE(B29),TEXT(B29,""yyyy""),""""))"),"")
K30: =IFERROR(__xludf.DUMMYFUNCTION("IF(ISBLANK(B30),"""",IF(ISDATE(B30),""X"",""""))"),"") | L30: =IFERROR(__xludf.DUMMYFUNCTION("IF(ISBLANK(B30),"""",IF(Or(I30=""Em Aberto"",ISBLANK(I30),NOT(ISDATE(B30))),"""",H30))"),"") | M30: =IFERROR(__xludf.DUMMYFUNCTION("IF(ISBLANK(B30),"""",IF(ISDATE(B30),TEXT(B30,""m""),""""))"),"") | N30: =IFERROR(__xludf.DUMMYFUNCTION("IF(M30="""","""",QUERY({'Dashboard-Dados'!$Y$2:$AA$13},""Select Col2 Where Col1=""&M30))"),"") | O30: =IFERROR(__xludf.DUMMYFUNCTION("IF(ISBLANK(B30),"""",IF(ISDATE(B30),TEXT(B30,""yyyy""),""""))"),"")
K31: =IFERROR(__xludf.DUMMYFUNCTION("IF(ISBLANK(B31),"""",IF(ISDATE(B31),""X"",""""))"),"") | L31: =IFERROR(__xludf.DUMMYFUNCTION("IF(ISBLANK(B31),"""",IF(Or(I31=""Em Aberto"",ISBLANK(I31),NOT(ISDATE(B31))),"""",H31))"),"") | M31: =IFERROR(__xludf.DUMMYFUNCTION("IF(ISBLANK(B31),"""",IF(ISDATE(B31),TEXT(B31,""m""),""""))"),"") | N31: =IFERROR(__xludf.DUMMYFUNCTION("IF(M31="""","""",QUERY({'Dashboard-Dados'!$Y$2:$AA$13},""Select Col2 Where Col1=""&M31))"),"") | O31: =IFERROR(__xludf.DUMMYFUNCTION("IF(ISBLANK(B31),"""",IF(ISDATE(B31),TEXT(B31,""yyyy""),""""))"),"")
K32: =IFERROR(__xludf.DUMMYFUNCTION("IF(ISBLANK(B32),"""",IF(ISDATE(B32),""X"",""""))"),"") | L32: =IFERROR(__xludf.DUMMYFUNCTION("IF(ISBLANK(B32),"""",IF(Or(I32=""Em Aberto"",ISBLANK(I32),NOT(ISDATE(B32))),"""",H32))"),"") | M32: =IFERROR(__xludf.DUMMYFUNCTION("IF(ISBLANK(B32),"""",IF(ISDATE(B32),TEXT(B32,""m""),""""))"),"") | N32: =IFERROR(__xludf.DUMMYFUNCTION("IF(M32="""","""",QUERY({'Dashboard-Dados'!$Y$2:$AA$13},""Select Col2 Where Col1=""&M32))"),"") | O32: =IFERROR(__xludf.DUMMYFUNCTION("IF(ISBLANK(B32),"""",IF(ISDATE(B32),TEXT(B32,""yyyy""),""""))"),"")
K33: =IFERROR(__xludf.DUMMYFUNCTION("IF(ISBLANK(B33),"""",IF(ISDATE(B33),""X"",""""))"),"") | L33: =IFERROR(__xludf.DUMMYFUNCTION("IF(ISBLANK(B33),"""",IF(Or(I33=""Em Aberto"",ISBLANK(I33),NOT(ISDATE(B33))),"""",H33))"),"") | M33: =IFERROR(__xludf.DUMMYFUNCTION("IF(ISBLANK(B33),"""",IF(ISDATE(B33),TEXT(B33,""m""),""""))"),"") | N33: =IFERROR(__xludf.DUMMYFUNCTION("IF(M33="""","""",QUERY({'Dashboard-Dados'!$Y$2:$AA$13},""Select Col2 Where Col1=""&M33))"),"") | O33: =IFERROR(__xludf.DUMMYFUNCTION("IF(ISBLANK(B33),"""",IF(ISDATE(B33),TEXT(B33,""yyyy""),""""))"),"")
K34: =IFERROR(__xludf.DUMMYFUNCTION("IF(ISBLANK(B34),"""",IF(ISDATE(B34),""X"",""""))"),"") | L34: =IFERROR(__xludf.DUMMYFUNCTION("IF(ISBLANK(B34),"""",IF(Or(I34=""Em Aberto"",ISBLANK(I34),NOT(ISDATE(B34))),"""",H34))"),"") | M34: =IFERROR(__xludf.DUMMYFUNCTION("IF(ISBLANK(B34),"""",IF(ISDATE(B34),TEXT(B34,""m""),""""))"),"") | N34: =IFERROR(__xludf.DUMMYFUNCTION("IF(M34="""","""",QUERY({'Dashboard-Dados'!$Y$2:$AA$13},""Select Col2 Where Col1=""&M34))"),"") | O34: =IFERROR(__xludf.DUMMYFUNCTION("IF(ISBLANK(B34),"""",IF(ISDATE(B34),TEXT(B34,""yyyy""),""""))"),"")
K35: =IFERROR(__xludf.DUMMYFUNCTION("IF(ISBLANK(B35),"""",IF(ISDATE(B35),""X"",""""))"),"") | L35: =IFERROR(__xludf.DUMMYFUNCTION("IF(ISBLANK(B35),"""",IF(Or(I35=""Em Aberto"",ISBLANK(I35),NOT(ISDATE(B35))),"""",H35))"),"") | M35: =IFERROR(__xludf.DUMMYFUNCTION("IF(ISBLANK(B35),"""",IF(ISDATE(B35),TEXT(B35,""m""),""""))"),"") | N35: =IFERROR(__xludf.DUMMYFUNCTION("IF(M35="""","""",QUERY({'Dashboard-Dados'!$Y$2:$AA$13},""Select Col2 Where Col1=""&M35))"),"") | O35: =IFERROR(__xludf.DUMMYFUNCTION("IF(ISBLANK(B35),"""",IF(ISDATE(B35),TEXT(B35,""yyyy""),""""))"),"")
K36: =IFERROR(__xludf.DUMMYFUNCTION("IF(ISBLANK(B36),"""",IF(ISDATE(B36),""X"",""""))"),"") | L36: =IFERROR(__xludf.DUMMYFUNCTION("IF(ISBLANK(B36),"""",IF(Or(I36=""Em Aberto"",ISBLANK(I36),NOT(ISDATE(B36))),"""",H36))"),"") | M36: =IFERROR(__xludf.DUMMYFUNCTION("IF(ISBLANK(B36),"""",IF(ISDATE(B36),TEXT(B36,""m""),""""))"),"") | N36: =IFERROR(__xludf.DUMMYFUNCTION("IF(M36="""","""",QUERY({'Dashboard-Dados'!$Y$2:$AA$13},""Select Col2 Where Col1=""&M36))"),"") | O36: =IFERROR(__xludf.DUMMYFUNCTION("IF(ISBLANK(B36),"""",IF(ISDATE(B36),TEXT(B36,""yyyy""),""""))"),"")
K37: =IFERROR(__xludf.DUMMYFUNCTION("IF(ISBLANK(B37),"""",IF(ISDATE(B37),""X"",""""))"),"") | L37: =IFERROR(__xludf.DUMMYFUNCTION("IF(ISBLANK(B37),"""",IF(Or(I37=""Em Aberto"",ISBLANK(I37),NOT(ISDATE(B37))),"""",H37))"),"") | M37: =IFERROR(__xludf.DUMMYFUNCTION("IF(ISBLANK(B37),"""",IF(ISDATE(B37),TEXT(B37,""m""),""""))"),"") | N37: =IFERROR(__xludf.DUMMYFUNCTION("IF(M37="""","""",QUERY({'Dashboard-Dados'!$Y$2:$AA$13},""Select Col2 Where Col1=""&M37))"),"") | O37: =IFERROR(__xludf.DUMMYFUNCTION("IF(ISBLANK(B37),"""",IF(ISDATE(B37),TEXT(B37,""yyyy""),""""))"),"")
K38: =IFERROR(__xludf.DUMMYFUNCTION("IF(ISBLANK(B38),"""",IF(ISDATE(B38),""X"",""""))"),"") | L38: =IFERROR(__xludf.DUMMYFUNCTION("IF(ISBLANK(B38),"""",IF(Or(I38=""Em Aberto"",ISBLANK(I38),NOT(ISDATE(B38))),"""",H38))"),"") | M38: =IFERROR(__xludf.DUMMYFUNCTION("IF(ISBLANK(B38),"""",IF(ISDATE(B38),TEXT(B38,""m""),""""))"),"") | N38: =IFERROR(__xludf.DUMMYFUNCTION("IF(M38="""","""",QUERY({'Dashboard-Dados'!$Y$2:$AA$13},""Select Col2 Where Col1=""&M38))"),"") | O38: =IFERROR(__xludf.DUMMYFUNCTION("IF(ISBLANK(B38),"""",IF(ISDATE(B38),TEXT(B38,""yyyy""),""""))"),"")
K39: =IFERROR(__xludf.DUMMYFUNCTION("IF(ISBLANK(B39),"""",IF(ISDATE(B39),""X"",""""))"),"") | L39: =IFERROR(__xludf.DUMMYFUNCTION("IF(ISBLANK(B39),"""",IF(Or(I39=""Em Aberto"",ISBLANK(I39),NOT(ISDATE(B39))),"""",H39))"),"") | M39: =IFERROR(__xludf.DUMMYFUNCTION("IF(ISBLANK(B39),"""",IF(ISDATE(B39),TEXT(B39,""m""),""""))"),"") | N39: =IFERROR(__xludf.DUMMYFUNCTION("IF(M39="""","""",QUERY({'Dashboard-Dados'!$Y$2:$AA$13},""Select Col2 Where Col1=""&M39))"),"") | O39: =IFERROR(__xludf.DUMMYFUNCTION("IF(ISBLANK(B39),"""",IF(ISDATE(B39),TEXT(B39,""yyyy""),""""))"),"")
K40: =IFERROR(__xludf.DUMMYFUNCTION("IF(ISBLANK(B40),"""",IF(ISDATE(B40),""X"",""""))"),"") | L40: =IFERROR(__xludf.DUMMYFUNCTION("IF(ISBLANK(B40),"""",IF(Or(I40=""Em Aberto"",ISBLANK(I40),NOT(ISDATE(B40))),"""",H40))"),"") | M40: =IFERROR(__xludf.DUMMYFUNCTION("IF(ISBLANK(B40),"""",IF(ISDATE(B40),TEXT(B40,""m""),""""))"),"") | N40: =IFERROR(__xludf.DUMMYFUNCTION("IF(M40="""","""",QUERY({'Dashboard-Dados'!$Y$2:$AA$13},""Select Col2 Where Col1=""&M40))"),"") | O40: =IFERROR(__xludf.DUMMYFUNCTION("IF(ISBLANK(B40),"""",IF(ISDATE(B40),TEXT(B40,""yyyy""),""""))"),"")
K41: =IFERROR(__xludf.DUMMYFUNCTION("IF(ISBLANK(B41),"""",IF(ISDATE(B41),""X"",""""))"),"") | L41: =IFERROR(__xludf.DUMMYFUNCTION("IF(ISBLANK(B41),"""",IF(Or(I41=""Em Aberto"",ISBLANK(I41),NOT(ISDATE(B41))),"""",H41))"),"") | M41: =IFERROR(__xludf.DUMMYFUNCTION("IF(ISBLANK(B41),"""",IF(ISDATE(B41),TEXT(B41,""m""),""""))"),"") | N41: =IFERROR(__xludf.DUMMYFUNCTION("IF(M41="""","""",QUERY({'Dashboard-Dados'!$Y$2:$AA$13},""Select Col2 Where Col1=""&M41))"),"") | O41: =IFERROR(__xludf.DUMMYFUNCTION("IF(ISBLANK(B41),"""",IF(ISDATE(B41),TEXT(B41,""yyyy""),""""))"),"")
...

Sheet Gastos
B1: CONTROLE DE GASTOS DE IMAGENS VETERINÁRIOS
B3: Data Pagamento | C3: Despesa ou Investimento | D3: Descrição | H3: Valor Pagamento | J3: Gasto | K3: Valor Despesa | L3: Mês-N | M3: Mês | N3: Ano
C4: Despesa | D4: gel | H4: xxxx | J4: =IFERROR(__xludf.DUMMYFUNCTION("IF(ISBLANK(B4),"""",IF(ISDATE(B4),""X"",""""))"),"") | K4: =IFERROR(__xludf.DUMMYFUNCTION("IF(ISBLANK(B4),"""",IF(ISDATE(B4),H4,""""))"),"") | L4: =IFERROR(__xludf.DUMMYFUNCTION("IF(ISBLANK(B4),"""",IF(ISDATE(B4),TEXT(B4,""m""),""""))"),"") | M4: =IFERROR(__xludf.DUMMYFUNCTION("IF(L4="""","""",QUERY({'Dashboard-Dados'!$Y$2:$AA$13},""Select Col2 Where Col1=""&L4))"),"") | N4: =IFERROR(__xludf.DUMMYFUNCTION("IF(ISBLANK(B4),"""",IF(ISDATE(B4),TEXT(B4,""yyyy""),""""))"),"")
C5: Investimento | J5: =IFERROR(__xludf.DUMMYFUNCTION("IF(ISBLANK(B5),"""",IF(ISDATE(B5),""X"",""""))"),"") | K5: =IFERROR(__xludf.DUMMYFUNCTION("IF(ISBLANK(B5),"""",IF(ISDATE(B5),H5,""""))"),"") | L5: =IFERROR(__xludf.DUMMYFUNCTION("IF(ISBLANK(B5),"""",IF(ISDATE(B5),TEXT(B5,""M""),""""))"),"") | M5: =IFERROR(__xludf.DUMMYFUNCTION("IF(L5="""","""",QUERY({'Dashboard-Dados'!$Y$2:$AA$13},""Select Col2 Where Col1=""&L5))"),"") | N5: =IFERROR(__xludf.DUMMYFUNCTION("IF(ISBLANK(B5),"""",IF(ISDATE(B5),TEXT(B5,""yyyy""),""""))"),"")
J6: =IFERROR(__xludf.DUMMYFUNCTION("IF(ISBLANK(B6),"""",IF(ISDATE(B6),""X"",""""))"),"") | K6: =IFERROR(__xludf.DUMMYFUNCTION("IF(ISBLANK(B6),"""",IF(ISDATE(B6),H6,""""))"),"") | L6: =IFERROR(__xludf.DUMMYFUNCTION("IF(ISBLANK(B6),"""",IF(ISDATE(B6),TEXT(B6,""M""),""""))"),"") | M6: =IFERROR(__xludf.DUMMYFUNCTION("IF(L6="""","""",QUERY({'Dashboard-Dados'!$Y$2:$AA$13},""Select Col2 Where Col1=""&L6))"),"") | N6: =IFERROR(__xludf.DUMMYFUNCTION("IF(ISBLANK(B6),"""",IF(ISDATE(B6),TEXT(B6,""yyyy""),""""))"),"")
J7: =IFERROR(__xludf.DUMMYFUNCTION("IF(ISBLANK(B7),"""",IF(ISDATE(B7),""X"",""""))"),"") | K7: =IFERROR(__xludf.DUMMYFUNCTION("IF(ISBLANK(B7),"""",IF(ISDATE(B7),H7,""""))"),"") | L7: =IFERROR(__xludf.DUMMYFUNCTION("IF(ISBLANK(B7),"""",IF(ISDATE(B7),TEXT(B7,""M""),""""))"),"") | M7: =IFERROR(__xludf.DUMMYFUNCTION("IF(L7="""","""",QUERY({'Dashboard-Dados'!$Y$2:$AA$13},""Select Col2 Where Col1=""&L7))"),"") | N7: =IFERROR(__xludf.DUMMYFUNCTION("IF(ISBLANK(B7),"""",IF(ISDATE(B7),TEXT(B7,""yyyy""),""""))"),"")
J8: =IFERROR(__xludf.DUMMYFUNCTION("IF(ISBLANK(B8),"""",IF(ISDATE(B8),""X"",""""))"),"") | K8: =IFERROR(__xludf.DUMMYFUNCTION("IF(ISBLANK(B8),"""",IF(ISDATE(B8),H8,""""))"),"") | L8: =IFERROR(__xludf.DUMMYFUNCTION("IF(ISBLANK(B8),"""",IF(ISDATE(B8),TEXT(B8,""M""),""""))"),"") | M8: =IFERROR(__xludf.DUMMYFUNCTION("IF(L8="""","""",QUERY({'Dashboard-Dados'!$Y$2:$AA$13},""Select Col2 Where Col1=""&L8))"),"") | N8: =IFERROR(__xludf.DUMMYFUNCTION("IF(ISBLANK(B8),"""",IF(ISDATE(B8),TEXT(B8,""yyyy""),""""))"),"")
J9: =IFERROR(__xludf.DUMMYFUNCTION("IF(ISBLANK(B9),"""",IF(ISDATE(B9),""X"",""""))"),"") | K9: =IFERROR(__xludf.DUMMYFUNCTION("IF(ISBLANK(B9),"""",IF(ISDATE(B9),H9,""""))"),"") | L9: =IFERROR(__xludf.DUMMYFUNCTION("IF(ISBLANK(B9),"""",IF(ISDATE(B9),TEXT(B9,""M""),""""))"),"") | M9: =IFERROR(__xludf.DUMMYFUNCTION("IF(L9="""","""",QUERY({'Dashboard-Dados'!$Y$2:$AA$13},""Select Col2 Where Col1=""&L9))"),"") | N9: =IFERROR(__xludf.DUMMYFUNCTION("IF(ISBLANK(B9),"""",IF(ISDATE(B9),TEXT(B9,""yyyy""),""""))"),"")
J10: =IFERROR(__xludf.DUMMYFUNCTION("IF(ISBLANK(B10),"""",IF(ISDATE(B10),""X"",""""))"),"") | K10: =IFERROR(__xludf.DUMMYFUNCTION("IF(ISBLANK(B10),"""",IF(ISDATE(B10),H10,""""))"),"") | L10: =IFERROR(__xludf.DUMMYFUNCTION("IF(ISBLANK(B10),"""",IF(ISDATE(B10),TEXT(B10,""M""),""""))"),"") | M10: =IFERROR(__xludf.DUMMYFUNCTION("IF(L10="""","""",QUERY({'Dashboard-Dados'!$Y$2:$AA$13},""Select Col2 Where Col1=""&L10))"),"") | N10: =IFERROR(__xludf.DUMMYFUNCTION("IF(ISBLANK(B10),"""",IF(ISDATE(B10),TEXT(B10,""yyyy""),""""))"),"")
J11: =IFERROR(__xludf.DUMMYFUNCTION("IF(ISBLANK(B11),"""",IF(ISDATE(B11),""X"",""""))"),"") | K11: =IFERROR(__xludf.DUMMYFUNCTION("IF(ISBLANK(B11),"""",IF(ISDATE(B11),H11,""""))"),"") | L11: =IFERROR(__xludf.DUMMYFUNCTION("IF(ISBLANK(B11),"""",IF(ISDATE(B11),TEXT(B11,""M""),""""))"),"") | M11: =IFERROR(__xludf.DUMMYFUNCTION("IF(L11="""","""",QUERY({'Dashboard-Dados'!$Y$2:$AA$13},""Select Col2 Where Col1=""&L11))"),"") | N11: =IFERROR(__xludf.DUMMYFUNCTION("IF(ISBLANK(B11),"""",IF(ISDATE(B11),TEXT(B11,""yyyy""),""""))"),"")
J12: =IFERROR(__xludf.DUMMYFUNCTION("IF(ISBLANK(B12),"""",IF(ISDATE(B12),""X"",""""))"),"") | K12: =IFERROR(__xludf.DUMMYFUNCTION("IF(ISBLANK(B12),"""",IF(ISDATE(B12),H12,""""))"),"") | L12: =IFERROR(__xludf.DUMMYFUNCTION("IF(ISBLANK(B12),"""",IF(ISDATE(B12),TEXT(B12,""M""),""""))"),"") | M12: =IFERROR(__xludf.DUMMYFUNCTION("IF(L12="""","""",QUERY({'Dashboard-Dados'!$Y$2:$AA$13},""Select Col2 Where Col1=""&L12))"),"") | N12: =IFERROR(__xludf.DUMMYFUNCTION("IF(ISBLANK(B12),"""",IF(ISDATE(B12),TEXT(B12,""yyyy""),""""))"),"")
J13: =IFERROR(__xludf.DUMMYFUNCTION("IF(ISBLANK(B13),"""",IF(ISDATE(B13),""X"",""""))"),"") | K13: =IFERROR(__xludf.DUMMYFUNCTION("IF(ISBLANK(B13),"""",IF(ISDATE(B13),H13,""""))"),"") | L13: =IFERROR(__xludf.DUMMYFUNCTION("IF(ISBLANK(B13),"""",IF(ISDATE(B13),TEXT(B13,""M""),""""))"),"") | M13: =IFERROR(__xludf.DUMMYFUNCTION("IF(L13="""","""",QUERY({'Dashboard-Dados'!$Y$2:$AA$13},""Select Col2 Where Col1=""&L13))"),"") | N13: =IFERROR(__xludf.DUMMYFUNCTION("IF(ISBLANK(B13),"""",IF(ISDATE(B13),TEXT(B13,""yyyy""),""""))"),"")
J14: =IFERROR(__xludf.DUMMYFUNCTION("IF(ISBLANK(B14),"""",IF(ISDATE(B14),""X"",""""))"),"") | K14: =IFERROR(__xludf.DUMMYFUNCTION("IF(ISBLANK(B14),"""",IF(ISDATE(B14),H14,""""))"),"") | L14: =IFERROR(__xludf.DUMMYFUNCTION("IF(ISBLANK(B14),"""",IF(ISDATE(B14),TEXT(B14,""M""),""""))"),"") | M14: =IFERROR(__xludf.DUMMYFUNCTION("IF(L14="""","""",QUERY({'Dashboard-Dados'!$Y$2:$AA$13},""Select Col2 Where Col1=""&L14))"),"") | N14: =IFERROR(__xludf.DUMMYFUNCTION("IF(ISBLANK(B14),"""",IF(ISDATE(B14),TEXT(B14,""yyyy""),""""))"),"")
J15: =IFERROR(__xludf.DUMMYFUNCTION("IF(ISBLANK(B15),"""",IF(ISDATE(B15),""X"",""""))"),"") | K15: =IFERROR(__xludf.DUMMYFUNCTION("IF(ISBLANK(B15),"""",IF(ISDATE(B15),H15,""""))"),"") | L15: =IFERROR(__xludf.DUMMYFUNCTION("IF(ISBLANK(B15),"""",IF(ISDATE(B15),TEXT(B15,""M""),""""))"),"") | M15: =IFERROR(__xludf.DUMMYFUNCTION("IF(L15="""","""",QUERY({'Dashboard-Dados'!$Y$2:$AA$13},""Select Col2 Where Col1=""&L15))"),"") | N15: =IFERROR(__xludf.DUMMYFUNCTION("IF(ISBLANK(B15),"""",IF(ISDATE(B15),TEXT(B15,""yyyy""),""""))"),"")
J16: =IFERROR(__xludf.DUMMYFUNCTION("IF(ISBLANK(B16),"""",IF(ISDATE(B16),""X"",""""))"),"") | K16: =IFERROR(__xludf.DUMMYFUNCTION("IF(ISBLANK(B16),"""",IF(ISDATE(B16),H16,""""))"),"") | L16: =IFERROR(__xludf.DUMMYFUNCTION("IF(ISBLANK(B16),"""",IF(ISDATE(B16),TEXT(B16,""M""),""""))"),"") | M16: =IFERROR(__xludf.DUMMYFUNCTION("IF(L16="""","""",QUERY({'Dashboard-Dados'!$Y$2:$AA$13},""Select Col2 Where Col1=""&L16))"),"") | N16: =IFERROR(__xludf.DUMMYFUNCTION("IF(ISBLANK(B16),"""",IF(ISDATE(B16),TEXT(B16,""yyyy""),""""))"),"")
J17: =IFERROR(__xludf.DUMMYFUNCTION("IF(ISBLANK(B17),"""",IF(ISDATE(B17),""X"",""""))"),"") | K17: =IFERROR(__xludf.DUMMYFUNCTION("IF(ISBLANK(B17),"""",IF(ISDATE(B17),H17,""""))"),"") | L17: =IFERROR(__xludf.DUMMYFUNCTION("IF(ISBLANK(B17),"""",IF(ISDATE(B17),TEXT(B17,""M""),""""))"),"") | M17: =IFERROR(__xludf.DUMMYFUNCTION("IF(L17="""","""",QUERY({'Dashboard-Dados'!$Y$2:$AA$13},""Select Col2 Where Col1=""&L17))"),"") | N17: =IFERROR(__xludf.DUMMYFUNCTION("IF(ISBLANK(B17),"""",IF(ISDATE(B17),TEXT(B17,""yyyy""),""""))"),"")
J18: =IFERROR(__xludf.DUMMYFUNCTION("IF(ISBLANK(B18),"""",IF(ISDATE(B18),""X"",""""))"),"") | K18: =IFERROR(__xludf.DUMMYFUNCTION("IF(ISBLANK(B18),"""",IF(ISDATE(B18),H18,""""))"),"") | L18: =IFERROR(__xludf.DUMMYFUNCTION("IF(ISBLANK(B18),"""",IF(ISDATE(B18),TEXT(B18,""M""),""""))"),"") | M18: =IFERROR(__xludf.DUMMYFUNCTION("IF(L18="""","""",QUERY({'Dashboard-Dados'!$Y$2:$AA$13},""Select Col2 Where Col1=""&L18))"),"") | N18: =IFERROR(__xludf.DUMMYFUNCTION("IF(ISBLANK(B18),"""",IF(ISDATE(B18),TEXT(B18,""yyyy""),""""))"),"")
J19: =IFERROR(__xludf.DUMMYFUNCTION("IF(ISBLANK(B19),"""",IF(ISDATE(B19),""X"",""""))"),"") | K19: =IFERROR(__xludf.DUMMYFUNCTION("IF(ISBLANK(B19),"""",IF(ISDATE(B19),H19,""""))"),"") | L19: =IFERROR(__xludf.DUMMYFUNCTION("IF(ISBLANK(B19),"""",IF(ISDATE(B19),TEXT(B19,""M""),""""))"),"") | M19: =IFERROR(__xludf.DUMMYFUNCTION("IF(L19="""","""",QUERY({'Dashboard-Dados'!$Y$2:$AA$13},""Select Col2 Where Col1=""&L19))"),"") | N19: =IFERROR(__xludf.DUMMYFUNCTION("IF(ISBLANK(B19),"""",IF(ISDATE(B19),TEXT(B19,""yyyy""),""""))"),"")
J20: =IFERROR(__xludf.DUMMYFUNCTION("IF(ISBLANK(B20),"""",IF(ISDATE(B20),""X"",""""))"),"") | K20: =IFERROR(__xludf.DUMMYFUNCTION("IF(ISBLANK(B20),"""",IF(ISDATE(B20),H20,""""))"),"") | L20: =IFERROR(__xludf.DUMMYFUNCTION("IF(ISBLANK(B20),"""",IF(ISDATE(B20),TEXT(B20,""M""),""""))"),"") | M20: =IFERROR(__xludf.DUMMYFUNCTION("IF(L20="""","""",QUERY({'Dashboard-Dados'!$Y$2:$AA$13},""Select Col2 Where Col1=""&L20))"),"") | N20: =IFERROR(__xludf.DUMMYFUNCTION("IF(ISBLANK(B20),"""",IF(ISDATE(B20),TEXT(B20,""yyyy""),""""))"),"")
J21: =IFERROR(__xludf.DUMMYFUNCTION("IF(ISBLANK(B21),"""",IF(ISDATE(B21),""X"",""""))"),"") | K21: =IFERROR(__xludf.DUMMYFUNCTION("IF(ISBLANK(B21),"""",IF(ISDATE(B21),H21,""""))"),"") | L21: =IFERROR(__xludf.DUMMYFUNCTION("IF(ISBLANK(B21),"""",IF(ISDATE(B21),TEXT(B21,""M""),""""))"),"") | M21: =IFERROR(__xludf.DUMMYFUNCTION("IF(L21="""","""",QUERY({'Dashboard-Dados'!$Y$2:$AA$13},""Select Col2 Where Col1=""&L21))"),"") | N21: =IFERROR(__xludf.DUMMYFUNCTION("IF(ISBLANK(B21),"""",IF(ISDATE(B21),TEXT(B21,""yyyy""),""""))"),"")
J22: =IFERROR(__xludf.DUMMYFUNCTION("IF(ISBLANK(B22),"""",IF(ISDATE(B22),""X"",""""))"),"") | K22: =IFERROR(__xludf.DUMMYFUNCTION("IF(ISBLANK(B22),"""",IF(ISDATE(B22),H22,""""))"),"") | L22: =IFERROR(__xludf.DUMMYFUNCTION("IF(ISBLANK(B22),"""",IF(ISDATE(B22),TEXT(B22,""M""),""""))"),"") | M22: =IFERROR(__xludf.DUMMYFUNCTION("IF(L22="""","""",QUERY({'Dashboard-Dados'!$Y$2:$AA$13},""Select Col2 Where Col1=""&L22))"),"") | N22: =IFERROR(__xludf.DUMMYFUNCTION("IF(ISBLANK(B22),"""",IF(ISDATE(B22),TEXT(B22,""yyyy""),""""))"),"")
J23: =IFERROR(__xludf.DUMMYFUNCTION("IF(ISBLANK(B23),"""",IF(ISDATE(B23),""X"",""""))"),"") | K23: =IFERROR(__xludf.DUMMYFUNCTION("IF(ISBLANK(B23),"""",IF(ISDATE(B23),H23,""""))"),"") | L23: =IFERROR(__xludf.DUMMYFUNCTION("IF(ISBLANK(B23),"""",IF(ISDATE(B23),TEXT(B23,""M""),""""))"),"") | M23: =IFERROR(__xludf.DUMMYFUNCTION("IF(L23="""","""",QUERY({'Dashboard-Dados'!$Y$2:$AA$13},""Select Col2 Where Col1=""&L23))"),"") | N23: =IFERROR(__xludf.DUMMYFUNCTION("IF(ISBLANK(B23),"""",IF(ISDATE(B23),TEXT(B23,""yyyy""),""""))"),"")
J24: =IFERROR(__xludf.DUMMYFUNCTION("IF(ISBLANK(B24),"""",IF(ISDATE(B24),""X"",""""))"),"") | K24: =IFERROR(__xludf.DUMMYFUNCTION("IF(ISBLANK(B24),"""",IF(ISDATE(B24),H24,""""))"),"") | L24: =IFERROR(__xludf.DUMMYFUNCTION("IF(ISBLANK(B24),"""",IF(ISDATE(B24),TEXT(B24,""M""),""""))"),"") | M24: =IFERROR(__xludf.DUMMYFUNCTION("IF(L24="""","""",QUERY({'Dashboard-Dados'!$Y$2:$AA$13},""Select Col2 Where Col1=""&L24))"),"") | N24: =IFERROR(__xludf.DUMMYFUNCTION("IF(ISBLANK(B24),"""",IF(ISDATE(B24),TEXT(B24,""yyyy""),""""))"),"")
J25: =IFERROR(__xludf.DUMMYFUNCTION("IF(ISBLANK(B25),"""",IF(ISDATE(B25),""X"",""""))"),"") | K25: =IFERROR(__xludf.DUMMYFUNCTION("IF(ISBLANK(B25),"""",IF(ISDATE(B25),H25,""""))"),"") | L25: =IFERROR(__xludf.DUMMYFUNCTION("IF(ISBLANK(B25),"""",IF(ISDATE(B25),TEXT(B25,""M""),""""))"),"") | M25: =IFERROR(__xludf.DUMMYFUNCTION("IF(L25="""","""",QUERY({'Dashboard-Dados'!$Y$2:$AA$13},""Select Col2 Where Col1=""&L25))"),"") | N25: =IFERROR(__xludf.DUMMYFUNCTION("IF(ISBLANK(B25),"""",IF(ISDATE(B25),TEXT(B25,""yyyy""),""""))"),"")
J26: =IFERROR(__xludf.DUMMYFUNCTION("IF(ISBLANK(B26),"""",IF(ISDATE(B26),""X"",""""))"),"") | K26: =IFERROR(__xludf.DUMMYFUNCTION("IF(ISBLANK(B26),"""",IF(ISDATE(B26),H26,""""))"),"") | L26: =IFERROR(__xludf.DUMMYFUNCTION("IF(ISBLANK(B26),"""",IF(ISDATE(B26),TEXT(B26,""M""),""""))"),"") | M26: =IFERROR(__xludf.DUMMYFUNCTION("IF(L26="""","""",QUERY({'Dashboard-Dados'!$Y$2:$AA$13},""Select Col2 Where Col1=""&L26))"),"") | N26: =IFERROR(__xludf.DUMMYFUNCTION("IF(ISBLANK(B26),"""",IF(ISDATE(B26),TEXT(B26,""yyyy""),""""))"),"")
J27: =IFERROR(__xludf.DUMMYFUNCTION("IF(ISBLANK(B27),"""",IF(ISDATE(B27),""X"",""""))"),"") | K27: =IFERROR(__xludf.DUMMYFUNCTION("IF(ISBLANK(B27),"""",IF(ISDATE(B27),H27,""""))"),"") | L27: =IFERROR(__xludf.DUMMYFUNCTION("IF(ISBLANK(B27),"""",IF(ISDATE(B27),TEXT(B27,""M""),""""))"),"") | M27: =IFERROR(__xludf.DUMMYFUNCTION("IF(L27="""","""",QUERY({'Dashboard-Dados'!$Y$2:$AA$13},""Select Col2 Where Col1=""&L27))"),"") | N27: =IFERROR(__xludf.DUMMYFUNCTION("IF(ISBLANK(B27),"""",IF(ISDATE(B27),TEXT(B27,""yyyy""),""""))"),"")
J28: =IFERROR(__xludf.DUMMYFUNCTION("IF(ISBLANK(B28),"""",IF(ISDATE(B28),""X"",""""))"),"") | K28: =IFERROR(__xludf.DUMMYFUNCTION("IF(ISBLANK(B28),"""",IF(ISDATE(B28),H28,""""))"),"") | L28: =IFERROR(__xludf.DUMMYFUNCTION("IF(ISBLANK(B28),"""",IF(ISDATE(B28),TEXT(B28,""M""),""""))"),"") | M28: =IFERROR(__xludf.DUMMYFUNCTION("IF(L28="""","""",QUERY({'Dashboard-Dados'!$Y$2:$AA$13},""Select Col2 Where Col1=""&L28))"),"") | N28: =IFERROR(__xludf.DUMMYFUNCTION("IF(ISBLANK(B28),"""",IF(ISDATE(B28),TEXT(B28,""yyyy""),""""))"),"")
J29: =IFERROR(__xludf.DUMMYFUNCTION("IF(ISBLANK(B29),"""",IF(ISDATE(B29),""X"",""""))"),"") | K29: =IFERROR(__xludf.DUMMYFUNCTION("IF(ISBLANK(B29),"""",IF(ISDATE(B29),H29,""""))"),"") | L29: =IFERROR(__xludf.DUMMYFUNCTION("IF(ISBLANK(B29),"""",IF(ISDATE(B29),TEXT(B29,""M""),""""))"),"") | M29: =IFERROR(__xludf.DUMMYFUNCTION("IF(L29="""","""",QUERY({'Dashboard-Dados'!$Y$2:$AA$13},""Select Col2 Where Col1=""&L29))"),"") | N29: =IFERROR(__xludf.DUMMYFUNCTION("IF(ISBLANK(B29),"""",IF(ISDATE(B29),TEXT(B29,""yyyy""),""""))"),"")
J30: =IFERROR(__xludf.DUMMYFUNCTION("IF(ISBLANK(B30),"""",IF(ISDATE(B30),""X"",""""))"),"") | K30: =IFERROR(__xludf.DUMMYFUNCTION("IF(ISBLANK(B30),"""",IF(ISDATE(B30),H30,""""))"),"") | L30: =IFERROR(__xludf.DUMMYFUNCTION("IF(ISBLANK(B30),"""",IF(ISDATE(B30),TEXT(B30,""M""),""""))"),"") | M30: =IFERROR(__xludf.DUMMYFUNCTION("IF(L30="""","""",QUERY({'Dashboard-Dados'!$Y$2:$AA$13},""Select Col2 Where Col1=""&L30))"),"") | N30: =IFERROR(__xludf.DUMMYFUNCTION("IF(ISBLANK(B30),"""",IF(ISDATE(B30),TEXT(B30,""yyyy""),""""))"),"")
J31: =IFERROR(__xludf.DUMMYFUNCTION("IF(ISBLANK(B31),"""",IF(ISDATE(B31),""X"",""""))"),"") | K31: =IFERROR(__xludf.DUMMYFUNCTION("IF(ISBLANK(B31),"""",IF(ISDATE(B31),H31,""""))"),"") | L31: =IFERROR(__xludf.DUMMYFUNCTION("IF(ISBLANK(B31),"""",IF(ISDATE(B31),TEXT(B31,""M""),""""))"),"") | M31: =IFERROR(__xludf.DUMMYFUNCTION("IF(L31="""","""",QUERY({'Dashboard-Dados'!$Y$2:$AA$13},""Select Col2 Where Col1=""&L31))"),"") | N31: =IFERROR(__xludf.DUMMYFUNCTION("IF(ISBLANK(B31),"""",IF(ISDATE(B31),TEXT(B31,""yyyy""),""""))"),"")
J32: =IFERROR(__xludf.DUMMYFUNCTION("IF(ISBLANK(B32),"""",IF(ISDATE(B32),""X"",""""))"),"") | K32: =IFERROR(__xludf.DUMMYFUNCTION("IF(ISBLANK(B32),"""",IF(ISDATE(B32),H32,""""))"),"") | L32: =IFERROR(__xludf.DUMMYFUNCTION("IF(ISBLANK(B32),"""",IF(ISDATE(B32),TEXT(B32,""M""),""""))"),"") | M32: =IFERROR(__xludf.DUMMYFUNCTION("IF(L32="""","""",QUERY({'Dashboard-Dados'!$Y$2:$AA$13},""Select Col2 Where Col1=""&L32))"),"") | N32: =IFERROR(__xludf.DUMMYFUNCTION("IF(ISBLANK(B32),"""",IF(ISDATE(B32),TEXT(B32,""yyyy""),""""))"),"")
J33: =IFERROR(__xludf.DUMMYFUNCTION("IF(ISBLANK(B33),"""",IF(ISDATE(B33),""X"",""""))"),"") | K33: =IFERROR(__xludf.DUMMYFUNCTION("IF(ISBLANK(B33),"""",IF(ISDATE(B33),H33,""""))"),"") | L33: =IFERROR(__xludf.DUMMYFUNCTION("IF(ISBLANK(B33),"""",IF(ISDATE(B33),TEXT(B33,""M""),""""))"),"") | M33: =IFERROR(__xludf.DUMMYFUNCTION("IF(L33="""","""",QUERY({'Dashboard-Dados'!$Y$2:$AA$13},""Select Col2 Where Col1=""&L33))"),"") | N33: =IFERROR(__xludf.DUMMYFUNCTION("IF(ISBLANK(B33),"""",IF(ISDATE(B33),TEXT(B33,""yyyy""),""""))"),"")
J34: =IFERROR(__xludf.DUMMYFUNCTION("IF(ISBLANK(B34),"""",IF(ISDATE(B34),""X"",""""))"),"") | K34: =IFERROR(__xludf.DUMMYFUNCTION("IF(ISBLANK(B34),"""",IF(ISDATE(B34),H34,""""))"),"") | L34: =IFERROR(__xludf.DUMMYFUNCTION("IF(ISBLANK(B34),"""",IF(ISDATE(B34),TEXT(B34,""M""),""""))"),"") | M34: =IFERROR(__xludf.DUMMYFUNCTION("IF(L34="""","""",QUERY({'Dashboard-Dados'!$Y$2:$AA$13},""Select Col2 Where Col1=""&L34))"),"") | N34: =IFERROR(__xludf.DUMMYFUNCTION("IF(ISBLANK(B34),"""",IF(ISDATE(B34),TEXT(B34,""yyyy""),""""))"),"")
J35: =IFERROR(__xludf.DUMMYFUNCTION("IF(ISBLANK(B35),"""",IF(ISDATE(B35),""X"",""""))"),"") | K35: =IFERROR(__xludf.DUMMYFUNCTION("IF(ISBLANK(B35),"""",IF(ISDATE(B35),H35,""""))"),"") | L35: =IFERROR(__xludf.DUMMYFUNCTION("IF(ISBLANK(B35),"""",IF(ISDATE(B35),TEXT(B35,""M""),""""))"),"") | M35: =IFERROR(__xludf.DUMMYFUNCTION("IF(L35="""","""",QUERY({'Dashboard-Dados'!$Y$2:$AA$13},""Select Col2 Where Col1=""&L35))"),"") | N35: =IFERROR(__xludf.DUMMYFUNCTION("IF(ISBLANK(B35),"""",IF(ISDATE(B35),TEXT(B35,""yyyy""),""""))"),"")
J36: =IFERROR(__xludf.DUMMYFUNCTION("IF(ISBLANK(B36),"""",IF(ISDATE(B36),""X"",""""))"),"") | K36: =IFERROR(__xludf.DUMMYFUNCTION("IF(ISBLANK(B36),"""",IF(ISDATE(B36),H36,""""))"),"") | L36: =IFERROR(__xludf.DUMMYFUNCTION("IF(ISBLANK(B36),"""",IF(ISDATE(B36),TEXT(B36,""M""),""""))"),"") | M36: =IFERROR(__xludf.DUMMYFUNCTION("IF(L36="""","""",QUERY({'Dashboard-Dados'!$Y$2:$AA$13},""Select Col2 Where Col1=""&L36))"),"") | N36: =IFERROR(__xludf.DUMMYFUNCTION("IF(ISBLANK(B36),"""",IF(ISDATE(B36),TEXT(B36,""yyyy""),""""))"),"")
J37: =IFERROR(__xludf.DUMMYFUNCTION("IF(ISBLANK(B37),"""",IF(ISDATE(B37),""X"",""""))"),"") | K37: =IFERROR(__xludf.DUMMYFUNCTION("IF(ISBLANK(B37),"""",IF(ISDATE(B37),H37,""""))"),"") | L37: =IFERROR(__xludf.DUMMYFUNCTION("IF(ISBLANK(B37),"""",IF(ISDATE(B37),TEXT(B37,""M""),""""))"),"") | M37: =IFERROR(__xludf.DUMMYFUNCTION("IF(L37="""","""",QUERY({'Dashboard-Dados'!$Y$2:$AA$13},""Select Col2 Where Col1=""&L37))"),"") | N37: =IFERROR(__xludf.DUMMYFUNCTION("IF(ISBLANK(B37),"""",IF(ISDATE(B37),TEXT(B37,""yyyy""),""""))"),"")
J38: =IFERROR(__xludf.DUMMYFUNCTION("IF(ISBLANK(B38),"""",IF(ISDATE(B38),""X"",""""))"),"") | K38: =IFERROR(__xludf.DUMMYFUNCTION("IF(ISBLANK(B38),"""",IF(ISDATE(B38),H38,""""))"),"") | L38: =IFERROR(__xludf.DUMMYFUNCTION("IF(ISBLANK(B38),"""",IF(ISDATE(B38),TEXT(B38,""M""),""""))"),"") | M38: =IFERROR(__xludf.DUMMYFUNCTION("IF(L38="""","""",QUERY({'Dashboard-Dados'!$Y$2:$AA$13},""Select Col2 Where Col1=""&L38))"),"") | N38: =IFERROR(__xludf.DUMMYFUNCTION("IF(ISBLANK(B38),"""",IF(ISDATE(B38),TEXT(B38,""yyyy""),""""))"),"")
J39: =IFERROR(__xludf.DUMMYFUNCTION("IF(ISBLANK(B39),"""",IF(ISDATE(B39),""X"",""""))"),"") | K39: =IFERROR(__xludf.DUMMYFUNCTION("IF(ISBLANK(B39),"""",IF(ISDATE(B39),H39,""""))"),"") | L39: =IFERROR(__xludf.DUMMYFUNCTION("IF(ISBLANK(B39),"""",IF(ISDATE(B39),TEXT(B39,""M""),""""))"),"") | M39: =IFERROR(__xludf.DUMMYFUNCTION("IF(L39="""","""",QUERY({'Dashboard-Dados'!$Y$2:$AA$13},""Select Col2 Where Col1=""&L39))"),"") | N39: =IFERROR(__xludf.DUMMYFUNCTION("IF(ISBLANK(B39),"""",IF(ISDATE(B39),TEXT(B39,""yyyy""),""""))"),"")
J40: =IFERROR(__xludf.DUMMYFUNCTION("IF(ISBLANK(B40),"""",IF(ISDATE(B40),""X"",""""))"),"") | K40: =IFERROR(__xludf.DUMMYFUNCTION("IF(ISBLANK(B40),"""",IF(ISDATE(B40),H40,""""))"),"") | L40: =IFERROR(__xludf.DUMMYFUNCTION("IF(ISBLANK(B40),"""",IF(ISDATE(B40),TEXT(B40,""M""),""""))"),"") | M40: =IFERROR(__xludf.DUMMYFUNCTION("IF(L40="""","""",QUERY({'Dashboard-Dados'!$Y$2:$AA$13},""Select Col2 Where Col1=""&L40))"),"") | N40: =IFERROR(__xludf.DUMMYFUNCTION("IF(ISBLANK(B40),"""",IF(ISDATE(B40),TEXT(B40,""yyyy""),""""))"),"")
J41: =IFERROR(__xludf.DUMMYFUNCTION("IF(ISBLANK(B41),"""",IF(ISDATE(B41),""X"",""""))"),"") | K41: =IFERROR(__xludf.DUMMYFUNCTION("IF(ISBLANK(B41),"""",IF(ISDATE(B41),H41,""""))"),"") | L41: =IFERROR(__xludf.DUMMYFUNCTION("IF(ISBLANK(B41),"""",IF(ISDATE(B41),TEXT(B41,""M""),""""))"),"") | M41: =IFERROR(__xludf.DUMMYFUNCTION("IF(L41="""","""",QUERY({'Dashboard-Dados'!$Y$2:$AA$13},""Select Col2 Where Col1=""&L41))"),"") | N41: =IFERROR(__xludf.DUMMYFUNCTION("IF(ISBLANK(B41),"""",IF(ISDATE(B41),TEXT(B41,""yyyy""),""""))"),"")
...

Sheet Parâmetros
B1: PARAMETROS PERSONALIZÁVEIS
B3: Ultrassonografia | D3: Cardiologia | F3: RaioX | H3: Tomografia | J3: Outros | L3: Formas de Pagamento
B4: US Abdominal | D4: Ecocardiograma | F4: 1 Projeção | L4: Dinheiro
B5: US Ocular | D5: Eletrocardiograma | F5: 2 Projeções | L5: Cartão de Crédito
B6: US Cervical | D6: Avaliação de pressão | F6: 3 Projeções | L6: Cartão de Débito
B7: Cistocentese | F7: 4 Projeções | L7: Transferencia Bancária
B8: Abdominocentese | F8: 5 Projeções | L8: Pix
B9: Toracocentese | F9: 6 Projeções | L9: PicPay
B10: A-FAST | F10: Projeção Adicional | L10: Cheque
B11: T-FAST | F11: Bula Timpânica | L11: Boleto
B12: Citologia Aspirativa | F12: Seios da Face | L12: Em Aberto
B13: US Crânio | F13: Maxila/Mandibula | L13: Outros
B14: US Articular | F14: Coluna
B15: Drenagem Ecoguiada | F15: Pesqquisa de Metástase
F16: Colapso de Traquéia
F17: Abdominal
F18: Displasia do Cotovelo
F19: Displasia Coxofemoral
F20: Esofagograma
F21: Gastrograma
F22: Urografia Excretora
F23: Cistografia
F24: Uretrocistografia
F25: Enema Baritado
F26: Mielografia

Sheet Parâmetros-Filtros
A1: =COLUMN() -> 1 | B1: =COLUMN() -> 2 | C1: =COLUMN() -> 3 | D1: =COLUMN() -> 4 | E1: =COLUMN() -> 5 | F1: =COLUMN() -> 6 | G1: =COLUMN() -> 7 | H1: =COLUMN() -> 8 | ... ATD1: =COLUMN() -> 1200
A6: {=IFNA(TRANSPOSE(INDEX('Parâmetros'!$B$4:$J3001,,MATCH(Exames!F4,'Parâmetros'!$B$3:$J$3,0))),"")} -> US Abdominal | B6: US Ocular | C6: US Cervical | D6: Cistocentese | E6: Abdominocentese | F6: Toracocentese | G6: A-FAST | H6: T-FAST | I6: Citologia Aspirativa | J6: US Crânio | K6: US Articular | L6: Drenagem Ecoguiada
A7: {=IFNA(TRANSPOSE(INDEX('Parâmetros'!$B$4:$J3001,,MATCH(Exames!F5,'Parâmetros'!$B$3:$J$3,0))),"")}
A8: {=IFNA(TRANSPOSE(INDEX('Parâmetros'!$B$4:$J3001,,MATCH(Exames!F6,'Parâmetros'!$B$3:$J$3,0))),"")}
A9: {=IFNA(TRANSPOSE(INDEX('Parâmetros'!$B$4:$J3001,,MATCH(Exames!F7,'Parâmetros'!$B$3:$J$3,0))),"")}
A10: {=IFNA(TRANSPOSE(INDEX('Parâmetros'!$B$4:$J3001,,MATCH(Exames!F8,'Parâmetros'!$B$3:$J$3,0))),"")}
A11: {=IFNA(TRANSPOSE(INDEX('Parâmetros'!$B$4:$J3001,,MATCH(Exames!F9,'Parâmetros'!$B$3:$J$3,0))),"")}
A12: {=IFNA(TRANSPOSE(INDEX('Parâmetros'!$B$4:$J3001,,MATCH(Exames!F10,'Parâmetros'!$B$3:$J$3,0))),"")}
A13: {=IFNA(TRANSPOSE(INDEX('Parâmetros'!$B$4:$J3001,,MATCH(Exames!F11,'Parâmetros'!$B$3:$J$3,0))),"")}
A14: {=IFNA(TRANSPOSE(INDEX('Parâmetros'!$B$4:$J3001,,MATCH(Exames!F12,'Parâmetros'!$B$3:$J$3,0))),"")}
A15: {=IFNA(TRANSPOSE(INDEX('Parâmetros'!$B$4:$J3001,,MATCH(Exames!F13,'Parâmetros'!$B$3:$J$3,0))),"")}
A16: {=IFNA(TRANSPOSE(INDEX('Parâmetros'!$B$4:$J3001,,MATCH(Exames!F14,'Parâmetros'!$B$3:$J$3,0))),"")}
A17: {=IFNA(TRANSPOSE(INDEX('Parâmetros'!$B$4:$J3001,,MATCH(Exames!F15,'Parâmetros'!$B$3:$J$3,0))),"")}
A18: {=IFNA(TRANSPOSE(INDEX('Parâmetros'!$B$4:$J3001,,MATCH(Exames!F16,'Parâmetros'!$B$3:$J$3,0))),"")}
A19: {=IFNA(TRANSPOSE(INDEX('Parâmetros'!$B$4:$J3001,,MATCH(Exames!F17,'Parâmetros'!$B$3:$J$3,0))),"")}
A20: {=IFNA(TRANSPOSE(INDEX('Parâmetros'!$B$4:$J3001,,MATCH(Exames!F18,'Parâmetros'!$B$3:$J$3,0))),"")}
A21: {=IFNA(TRANSPOSE(INDEX('Parâmetros'!$B$4:$J3001,,MATCH(Exames!F19,'Parâmetros'!$B$3:$J$3,0))),"")}
A22: {=IFNA(TRANSPOSE(INDEX('Parâmetros'!$B$4:$J3001,,MATCH(Exames!F20,'Parâmetros'!$B$3:$J$3,0))),"")}
A23: {=IFNA(TRANSPOSE(INDEX('Parâmetros'!$B$4:$J3001,,MATCH(Exames!F21,'Parâmetros'!$B$3:$J$3,0))),"")}
A24: {=IFNA(TRANSPOSE(INDEX('Parâmetros'!$B$4:$J3001,,MATCH(Exames!F22,'Parâmetros'!$B$3:$J$3,0))),"")}
A25: {=IFNA(TRANSPOSE(INDEX('Parâmetros'!$B$4:$J3001,,MATCH(Exames!F23,'Parâmetros'!$B$3:$J$3,0))),"")}
A26: {=IFNA(TRANSPOSE(INDEX('Parâmetros'!$B$4:$J3001,,MATCH(Exames!F24,'Parâmetros'!$B$3:$J$3,0))),"")}
A27: {=IFNA(TRANSPOSE(INDEX('Parâmetros'!$B$4:$J3001,,MATCH(Exames!F25,'Parâmetros'!$B$3:$J$3,0))),"")}
A28: {=IFNA(TRANSPOSE(INDEX('Parâmetros'!$B$4:$J3001,,MATCH(Exames!F26,'Parâmetros'!$B$3:$J$3,0))),"")}
A29: {=IFNA(TRANSPOSE(INDEX('Parâmetros'!$B$4:$J3001,,MATCH(Exames!F27,'Parâmetros'!$B$3:$J$3,0))),"")}
A30: {=IFNA(TRANSPOSE(INDEX('Parâmetros'!$B$4:$J3001,,MATCH(Exames!F28,'Parâmetros'!$B$3:$J$3,0))),"")}
A31: {=IFNA(TRANSPOSE(INDEX('Parâmetros'!$B$4:$J3001,,MATCH(Exames!F29,'Parâmetros'!$B$3:$J$3,0))),"")}
A32: {=IFNA(TRANSPOSE(INDEX('Parâmetros'!$B$4:$J3001,,MATCH(Exames!F30,'Parâmetros'!$B$3:$J$3,0))),"")}
A33: {=IFNA(TRANSPOSE(INDEX('Parâmetros'!$B$4:$J3001,,MATCH(Exames!F31,'Parâmetros'!$B$3:$J$3,0))),"")}
A34: {=IFNA(TRANSPOSE(INDEX('Parâmetros'!$B$4:$J3001,,MATCH(Exames!F32,'Parâmetros'!$B$3:$J$3,0))),"")}
A35: {=IFNA(TRANSPOSE(INDEX('Parâmetros'!$B$4:$J3001,,MATCH(Exames!F33,'Parâmetros'!$B$3:$J$3,0))),"")}
A36: {=IFNA(TRANSPOSE(INDEX('Parâmetros'!$B$4:$J3001,,MATCH(Exames!F34,'Parâmetros'!$B$3:$J$3,0))),"")}
A37: {=IFNA(TRANSPOSE(INDEX('Parâmetros'!$B$4:$J3001,,MATCH(Exames!F35,'Parâmetros'!$B$3:$J$3,0))),"")}
A38: {=IFNA(TRANSPOSE(INDEX('Parâmetros'!$B$4:$J3001,,MATCH(Exames!F36,'Parâmetros'!$B$3:$J$3,0))),"")}
A39: {=IFNA(TRANSPOSE(INDEX('Parâmetros'!$B$4:$J3001,,MATCH(Exames!F37,'Parâmetros'!$B$3:$J$3,0))),"")}
A40: {=IFNA(TRANSPOSE(INDEX('Parâmetros'!$B$4:$J3001,,MATCH(Exames!F38,'Parâmetros'!$B$3:$J$3,0))),"")}
A41: {=IFNA(TRANSPOSE(INDEX('Parâmetros'!$B$4:$J3001,,MATCH(Exames!F39,'Parâmetros'!$B$3:$J$3,0))),"")}
A42: {=IFNA(TRANSPOSE(INDEX('Parâmetros'!$B$4:$J3001,,MATCH(Exames!F40,'Parâmetros'!$B$3:$J$3,0))),"")}
A43: {=IFNA(TRANSPOSE(INDEX('Parâmetros'!$B$4:$J3001,,MATCH(Exames!F41,'Parâmetros'!$B$3:$J$3,0))),"")}
A44: {=IFNA(TRANSPOSE(INDEX('Parâmetros'!$B$4:$J3001,,MATCH(Exames!F42,'Parâmetros'!$B$3:$J$3,0))),"")}
...

Sheet Dashboard-Dados
A1: Ano | B1: Mês-N | C1: Mês | D1: Receita | E1: Despesa | F1: Lucro | G1: Qtd Exames | H1: Linha | K1: Colunas | Q1: Colunas | U1: =IFERROR(__xludf.DUMMYFUNCTION("QUERY({J1:M1201},""Select Col1 Where Col4 Is Not Null Label Col1 'Ano Receitas'"")"),"Ano Receitas") -> Ano Receitas | V1: =IFERROR(__xludf.DUMMYFUNCTION("QUERY({P1:S1201},""Select Col1 Where Col4 Is Not Null Label Col1 'Ano Despesas'"")"),"Ano Despesas") -> Ano Despesas | W1: Lista Anos | Y1: Mês | Z1: Abrev. | AA1: Descrição | AB1: Exames | AC1: Diferença | AE1: Receitas | AF1: =IFERROR(GETPIVOTDATA("SUM de Receita",Dashboard!$AK$48),0) -> 0
A2: =IFERROR(__xludf.DUMMYFUNCTION("ARRAYFORMULA(SPLIT(FLATTEN(QUERY({W2:W1201},""Select * Where Col1 Is Not Null"") & ""|"" & TRANSPOSE(Y2:Y13)), ""|""))"),"#N/A") -> #N/A | C2: =IFNA(VLOOKUP('Dashboard-Dados'!B2,'Dashboard-Dados'!$Y$2:$AA$13,2),"") | D2: =IFERROR(GETPIVOTDATA("Valor Recebido",'Dashboard-Dados'!$J$1,$A$1,A2,$B$1,B2),0) -> 0 | E2: =IFERROR(GETPIVOTDATA("Valor Despesa",'Dashboard-Dados'!$P$1,$A$1,A2,$B$1,B2),0) -> 0 | F2: =D2-E2 -> 0 | G2: =IFERROR(GETPIVOTDATA("Exame",'Dashboard-Dados'!$J$1,$A$1,A2,$B$1,B2),0) -> 0 | H2: =ROW() -> 2 | J2: Linhas | K2: Valores | P2: Linhas | Q2: Valores | W2: =IFERROR(__xludf.DUMMYFUNCTION("SORT(UNIQUE(TRANSPOSE((IFERROR(SPLIT(TEXTJOIN("","",TRUE, IFERROR(TEXTJOIN("","",TRUE,U2:U1201),""""), IFERROR(TEXTJOIN("","",TRUE,V2:V1201),"""") ),"",""),"""")))),1,TRUE)"),"") | Y2: 1 | Z2: =PROPER(TEXT(DATE(1900,Y2,1),"mmm")) -> Jan. | AA2: =PROPER(TEXT(DATE(1900,Y2,1),"mmMm")) -> Janeiro | AB2: =IFNA(INDIRECT(ADDRESS(Y2+$Z$15,$AB$15)), 0) -> 0 | AC2: =0 -> 0 | AE2: Despesas | AF2: =IFERROR(GETPIVOTDATA("SUM de Despesa",Dashboard!$AK$48),0) -> 0
A3: =IFERROR(__xludf.DUMMYFUNCTION("""COMPUTED_VALUE"""),"#N/A") -> #N/A | C3: =IFNA(VLOOKUP('Dashboard-Dados'!B3,'Dashboard-Dados'!$Y$2:$AA$13,2),"") | D3: =IFERROR(GETPIVOTDATA("Valor Recebido",'Dashboard-Dados'!$J$1,$A$1,A3,$B$1,B3),0) -> 0 | E3: =IFERROR(GETPIVOTDATA("Valor Despesa",'Dashboard-Dados'!$P$1,$A$1,A3,$B$1,B3),0) -> 0 | F3: =D3-E3 -> 0 | G3: =IFERROR(GETPIVOTDATA("Exame",'Dashboard-Dados'!$J$1,$A$1,A3,$B$1,B3),0) -> 0 | H3: =ROW() -> 3 | Y3: =Y2+1 -> 2 | Z3: =PROPER(TEXT(DATE(1900,Y3,1),"mmm")) -> Fev. | AA3: =PROPER(TEXT(DATE(1900,Y3,1),"mmMm")) -> Fevereiro | AB3: =IFNA(INDIRECT(ADDRESS(Y3+$Z$15,$AB$15)), 0) -> 0 | AC3: =AB3-AB2 -> 0 | AE3: Lucro | AF3: =IFERROR(GETPIVOTDATA("SUM de Lucro",Dashboard!$AK$48),0) -> 0
A4: =IFERROR(__xludf.DUMMYFUNCTION("""COMPUTED_VALUE"""),"#N/A") -> #N/A | C4: =IFNA(VLOOKUP('Dashboard-Dados'!B4,'Dashboard-Dados'!$Y$2:$AA$13,2),"") | D4: =IFERROR(GETPIVOTDATA("Valor Recebido",'Dashboard-Dados'!$J$1,$A$1,A4,$B$1,B4),0) -> 0 | E4: =IFERROR(GETPIVOTDATA("Valor Despesa",'Dashboard-Dados'!$P$1,$A$1,A4,$B$1,B4),0) -> 0 | F4: =D4-E4 -> 0 | G4: =IFERROR(GETPIVOTDATA("Exame",'Dashboard-Dados'!$J$1,$A$1,A4,$B$1,B4),0) -> 0 | H4: =ROW() -> 4 | Y4: =Y3+1 -> 3 | Z4: =PROPER(TEXT(DATE(1900,Y4,1),"mmm")) -> Mar. | AA4: =PROPER(TEXT(DATE(1900,Y4,1),"mmMm")) -> Março | AB4: =IFNA(INDIRECT(ADDRESS(Y4+$Z$15,$AB$15)), 0) -> 0 | AC4: =AB4-AB3 -> 0 | AF4: Total | AG4: Max
A5: =IFERROR(__xludf.DUMMYFUNCTION("""COMPUTED_VALUE"""),"#N/A") -> #N/A | C5: =IFNA(VLOOKUP('Dashboard-Dados'!B5,'Dashboard-Dados'!$Y$2:$AA$13,2),"") | D5: =IFERROR(GETPIVOTDATA("Valor Recebido",'Dashboard-Dados'!$J$1,$A$1,A5,$B$1,B5),0) -> 0 | E5: =IFERROR(GETPIVOTDATA("Valor Despesa",'Dashboard-Dados'!$P$1,$A$1,A5,$B$1,B5),0) -> 0 | F5: =D5-E5 -> 0 | G5: =IFERROR(GETPIVOTDATA("Exame",'Dashboard-Dados'!$J$1,$A$1,A5,$B$1,B5),0) -> 0 | H5: =ROW() -> 5 | Y5: =Y4+1 -> 4 | Z5: =PROPER(TEXT(DATE(1900,Y5,1),"mmm")) -> Abr. | AA5: =PROPER(TEXT(DATE(1900,Y5,1),"mmMm")) -> Abril | AB5: =IFNA(INDIRECT(ADDRESS(Y5+$Z$15,$AB$15)), 0) -> 0 | AC5: =AB5-AB4 -> 0 | AE5: Exames | AF5: =IFERROR(GETPIVOTDATA("SUM de Qtd Exames",Dashboard!$AK$48),0) -> 0 | AG5: =IFERROR(GETPIVOTDATA("MAX de Qtd Exames",Dashboard!$AK$48),0) -> 0
A6: =IFERROR(__xludf.DUMMYFUNCTION("""COMPUTED_VALUE"""),"#N/A") -> #N/A | C6: =IFNA(VLOOKUP('Dashboard-Dados'!B6,'Dashboard-Dados'!$Y$2:$AA$13,2),"") | D6: =IFERROR(GETPIVOTDATA("Valor Recebido",'Dashboard-Dados'!$J$1,$A$1,A6,$B$1,B6),0) -> 0 | E6: =IFERROR(GETPIVOTDATA("Valor Despesa",'Dashboard-Dados'!$P$1,$A$1,A6,$B$1,B6),0) -> 0 | F6: =D6-E6 -> 0 | G6: =IFERROR(GETPIVOTDATA("Exame",'Dashboard-Dados'!$J$1,$A$1,A6,$B$1,B6),0) -> 0 | H6: =ROW() -> 6 | Y6: =Y5+1 -> 5 | Z6: =PROPER(TEXT(DATE(1900,Y6,1),"mmm")) -> Mai. | AA6: =PROPER(TEXT(DATE(1900,Y6,1),"mmMm")) -> Maio | AB6: =IFNA(INDIRECT(ADDRESS(Y6+$Z$15,$AB$15)), 0) -> 0 | AC6: =AB6-AB5 -> 0
A7: =IFERROR(__xludf.DUMMYFUNCTION("""COMPUTED_VALUE"""),"#N/A") -> #N/A | C7: =IFNA(VLOOKUP('Dashboard-Dados'!B7,'Dashboard-Dados'!$Y$2:$AA$13,2),"") | D7: =IFERROR(GETPIVOTDATA("Valor Recebido",'Dashboard-Dados'!$J$1,$A$1,A7,$B$1,B7),0) -> 0 | E7: =IFERROR(GETPIVOTDATA("Valor Despesa",'Dashboard-Dados'!$P$1,$A$1,A7,$B$1,B7),0) -> 0 | F7: =D7-E7 -> 0 | G7: =IFERROR(GETPIVOTDATA("Exame",'Dashboard-Dados'!$J$1,$A$1,A7,$B$1,B7),0) -> 0 | H7: =ROW() -> 7 | Y7: =Y6+1 -> 6 | Z7: =PROPER(TEXT(DATE(1900,Y7,1),"mmm")) -> Jun. | AA7: =PROPER(TEXT(DATE(1900,Y7,1),"mmMm")) -> Junho | AB7: =IFNA(INDIRECT(ADDRESS(Y7+$Z$15,$AB$15)), 0) -> 0 | AC7: =AB7-AB6 -> 0 | AE7: Faixas
A8: =IFERROR(__xludf.DUMMYFUNCTION("""COMPUTED_VALUE"""),"#N/A") -> #N/A | C8: =IFNA(VLOOKUP('Dashboard-Dados'!B8,'Dashboard-Dados'!$Y$2:$AA$13,2),"") | D8: =IFERROR(GETPIVOTDATA("Valor Recebido",'Dashboard-Dados'!$J$1,$A$1,A8,$B$1,B8),0) -> 0 | E8: =IFERROR(GETPIVOTDATA("Valor Despesa",'Dashboard-Dados'!$P$1,$A$1,A8,$B$1,B8),0) -> 0 | F8: =D8-E8 -> 0 | G8: =IFERROR(GETPIVOTDATA("Exame",'Dashboard-Dados'!$J$1,$A$1,A8,$B$1,B8),0) -> 0 | H8: =ROW() -> 8 | Y8: =Y7+1 -> 7 | Z8: =PROPER(TEXT(DATE(1900,Y8,1),"mmm")) -> Jul. | AA8: =PROPER(TEXT(DATE(1900,Y8,1),"mmMm")) -> Julho | AB8: =IFNA(INDIRECT(ADDRESS(Y8+$Z$15,$AB$15)), 0) -> 0 | AC8: =AB8-AB7 -> 0 | AE8: Cor | AF8: Intervalo | AG8: HEX Cor | AH8: Linha | AI8: Alvo
A9: =IFERROR(__xludf.DUMMYFUNCTION("""COMPUTED_VALUE"""),"#N/A") -> #N/A | C9: =IFNA(VLOOKUP('Dashboard-Dados'!B9,'Dashboard-Dados'!$Y$2:$AA$13,2),"") | D9: =IFERROR(GETPIVOTDATA("Valor Recebido",'Dashboard-Dados'!$J$1,$A$1,A9,$B$1,B9),0) -> 0 | E9: =IFERROR(GETPIVOTDATA("Valor Despesa",'Dashboard-Dados'!$P$1,$A$1,A9,$B$1,B9),0) -> 0 | F9: =D9-E9 -> 0 | G9: =IFERROR(GETPIVOTDATA("Exame",'Dashboard-Dados'!$J$1,$A$1,A9,$B$1,B9),0) -> 0 | H9: =ROW() -> 9 | Y9: =Y8+1 -> 8 | Z9: =PROPER(TEXT(DATE(1900,Y9,1),"mmm")) -> Ago. | AA9: =PROPER(TEXT(DATE(1900,Y9,1),"mmMm")) -> Agosto | AB9: =IFNA(INDIRECT(ADDRESS(Y9+$Z$15,$AB$15)), 0) -> 0 | AC9: =AB9-AB8 -> 0 | AE9: =COLUMN() -> 31 | AF9: =COLUMN() -> 32 | AG9: =COLUMN() -> 33 | AH9: =COLUMN() -> 34 | AI9: =COLUMN() -> 35
A10: =IFERROR(__xludf.DUMMYFUNCTION("""COMPUTED_VALUE"""),"#N/A") -> #N/A | C10: =IFNA(VLOOKUP('Dashboard-Dados'!B10,'Dashboard-Dados'!$Y$2:$AA$13,2),"") | D10: =IFERROR(GETPIVOTDATA("Valor Recebido",'Dashboard-Dados'!$J$1,$A$1,A10,$B$1,B10),0) -> 0 | E10: =IFERROR(GETPIVOTDATA("Valor Despesa",'Dashboard-Dados'!$P$1,$A$1,A10,$B$1,B10),0) -> 0 | F10: =D10-E10 -> 0 | G10: =IFERROR(GETPIVOTDATA("Exame",'Dashboard-Dados'!$J$1,$A$1,A10,$B$1,B10),0) -> 0 | H10: =ROW() -> 10 | Y10: =Y9+1 -> 9 | Z10: =PROPER(TEXT(DATE(1900,Y10,1),"mmm")) -> Set. | AA10: =PROPER(TEXT(DATE(1900,Y10,1),"mmMm")) -> Setembro | AB10: =IFNA(INDIRECT(ADDRESS(Y10+$Z$15,$AB$15)), 0) -> 0 | AC10: =AB10-AB9 -> 0 | AE10: Branca | AF10: 0 | AG10: #ffffff | AH10: =ROW() -> 10 | AI10: =$AF$17=AE10 -> TRUE
A11: =IFERROR(__xludf.DUMMYFUNCTION("""COMPUTED_VALUE"""),"#N/A") -> #N/A | C11: =IFNA(VLOOKUP('Dashboard-Dados'!B11,'Dashboard-Dados'!$Y$2:$AA$13,2),"") | D11: =IFERROR(GETPIVOTDATA("Valor Recebido",'Dashboard-Dados'!$J$1,$A$1,A11,$B$1,B11),0) -> 0 | E11: =IFERROR(GETPIVOTDATA("Valor Despesa",'Dashboard-Dados'!$P$1,$A$1,A11,$B$1,B11),0) -> 0 | F11: =D11-E11 -> 0 | G11: =IFERROR(GETPIVOTDATA("Exame",'Dashboard-Dados'!$J$1,$A$1,A11,$B$1,B11),0) -> 0 | H11: =ROW() -> 11 | Y11: =Y10+1 -> 10 | Z11: =PROPER(TEXT(DATE(1900,Y11,1),"mmm")) -> Out. | AA11: =PROPER(TEXT(DATE(1900,Y11,1),"mmMm")) -> Outubro | AB11: =IFNA(INDIRECT(ADDRESS(Y11+$Z$15,$AB$15)), 0) -> 0 | AC11: =AB11-AB10 -> 0 | AE11: Amarela | AF11: 1 | AG11: #ffff00 | AH11: =ROW() -> 11 | AI11: =$AF$17=AE11 -> FALSE
A12: =IFERROR(__xludf.DUMMYFUNCTION("""COMPUTED_VALUE"""),"#N/A") -> #N/A | C12: =IFNA(VLOOKUP('Dashboard-Dados'!B12,'Dashboard-Dados'!$Y$2:$AA$13,2),"") | D12: =IFERROR(GETPIVOTDATA("Valor Recebido",'Dashboard-Dados'!$J$1,$A$1,A12,$B$1,B12),0) -> 0 | E12: =IFERROR(GETPIVOTDATA("Valor Despesa",'Dashboard-Dados'!$P$1,$A$1,A12,$B$1,B12),0) -> 0 | F12: =D12-E12 -> 0 | G12: =IFERROR(GETPIVOTDATA("Exame",'Dashboard-Dados'!$J$1,$A$1,A12,$B$1,B12),0) -> 0 | H12: =ROW() -> 12 | Y12: =Y11+1 -> 11 | Z12: =PROPER(TEXT(DATE(1900,Y12,1),"mmm")) -> Nov. | AA12: =PROPER(TEXT(DATE(1900,Y12,1),"mmMm")) -> Novembro | AB12: =IFNA(INDIRECT(ADDRESS(Y12+$Z$15,$AB$15)), 0) -> 0 | AC12: =AB12-AB11 -> 0 | AE12: Roxa | AF12: 71 | AG12: #674ea7 | AH12: =ROW() -> 12 | AI12: =$AF$17=AE12 -> FALSE
